Workbook

Sheet Instructions
A2: INSTRUCTION on How to USE this report
A3: 1) Enter all FML claim details in "Data Report Sheet" TAB - make sure all Invoice number is correct
A4: 2) Paste the report downloaded from fml on "PDI report", FSC report and" Warranty report" TABS
A5: 3) Make sure that duplication data is not pasted on the report sheet
A6: 4) Goto "DATA" in menu - Click on "Refresh All"

Sheet Data Report sheet
A1: GAPL Claim invoice number | B1: GAPL Internal Claim No | C1: GAPL Invoice Date | D1: Invoice Value | E1: Type of Claim (PDI/Warranty/Service Campaign/Breakdown/Others) | F1: Claim status | G1: Claim Passed Amount | H1: Rejected Amount | I1: Payment Date | J1: Remarks | K1: Claim Month | L1: Claim Year
A2: WCI25C000102 | B2: 356 | C2: 45743 | D2: 2765 | E2: Warranty | F2: Accepted | G2: 2765 | H2: =IF(ISERROR(VLOOKUP(A2,Report!A:D,4,FALSE)),"NOT FOUND",VLOOKUP(A2,Report!A:D,4,FALSE)) -> NOT FOUND | I2: 45813 | K2: =MONTH(C2) -> 3 | L2: =YEAR(C2) -> 2025
A3: WCI25C000103 | B3: 357 | C3: 45743 | D3: 2588 | E3: Warranty | F3: Accepted | G3: 2588 | H3: =IF(ISERROR(VLOOKUP(A3,Report!A:D,4,FALSE)),"NOT FOUND",VLOOKUP(A3,Report!A:D,4,FALSE)) -> NOT FOUND | I3: 45813 | K3: =MONTH(C3) -> 3 | L3: =YEAR(C3) -> 2025
A4: WCI26C000001 | B4: 358 | C4: 45777 | D4: 1465 | E4: Warranty | F4: REJECTED | G4: =IF(ISERROR(VLOOKUP(A4,Report!A:D,3,FALSE)),"NOT FOUND",VLOOKUP(A4,Report!A:D,3,FALSE)) -> 0 | H4: =IF(ISERROR(VLOOKUP(A4,Report!A:D,4,FALSE)),"NOT FOUND",VLOOKUP(A4,Report!A:D,4,FALSE)) -> 1464.91 | I4: =IF(ISERROR(VLOOKUP(A4,Report!A:D,2,FALSE)),"NOT FOUND",VLOOKUP(A4,Report!A:D,2,FALSE)) -> 29-05-2025 | K4: =MONTH(C4) -> 4 | L4: =YEAR(C4) -> 2025
A5: WCI26C000002 | B5: 359 | C5: 45777 | D5: 2187 | E5: Warranty | F5: =IF((D5-G5)<10,"Accepted","Partial/Rejected") -> Accepted | G5: =IF(ISERROR(VLOOKUP(A5,Report!A:D,3,FALSE)),"NOT FOUND",VLOOKUP(A5,Report!A:D,3,FALSE)) -> 2186.85 | H5: =IF(ISERROR(VLOOKUP(A5,Report!A:D,4,FALSE)),"NOT FOUND",VLOOKUP(A5,Report!A:D,4,FALSE)) -> 0 | I5: =IF(ISERROR(VLOOKUP(A5,Report!A:D,2,FALSE)),"NOT FOUND",VLOOKUP(A5,Report!A:D,2,FALSE)) -> 29-05-2025 | K5: =MONTH(C5) -> 4 | L5: =YEAR(C5) -> 2025
A6: PCI26C000001 | C6: 45770 | D6: 7375 | E6: REMOTE SERVICE CAMP | F6: =IF((D6-G6)<10,"Accepted","Partial/Rejected") -> Accepted | G6: 7375 | H6: =IF(ISERROR(VLOOKUP(A6,Report!A:D,4,FALSE)),"NOT FOUND",VLOOKUP(A6,Report!A:D,4,FALSE)) -> NOT FOUND | I6: 45831 | K6: =MONTH(C6) -> 4 | L6: =YEAR(C6) -> 2025
A7: PCI26C000002 | C7: 45770 | D7: 8661 | E7: REMOTE SERVICE CAMP | F7: =IF((D7-G7)<10,"Accepted","Partial/Rejected") -> Accepted | G7: 8661.2 | H7: =IF(ISERROR(VLOOKUP(A7,Report!A:D,4,FALSE)),"NOT FOUND",VLOOKUP(A7,Report!A:D,4,FALSE)) -> NOT FOUND | I7: 45831 | K7: =MONTH(C7) -> 4 | L7: =YEAR(C7) -> 2025
A8: PCI26C000003 | C8: 45777 | D8: 8685 | E8: REMOTE SERVICE CAMP | F8: =IF((D8-G8)<10,"Accepted","Partial/Rejected") -> Accepted | G8: 8684.8 | H8: =IF(ISERROR(VLOOKUP(A8,Report!A:D,4,FALSE)),"NOT FOUND",VLOOKUP(A8,Report!A:D,4,FALSE)) -> NOT FOUND | I8: 45868 | K8: =MONTH(C8) -> 4 | L8: =YEAR(C8) -> 2025
A9: PCI26C000004 | C9: 45777 | D9: 8484 | E9: REMOTE SERVICE CAMP | F9: =IF((D9-G9)<10,"Accepted","Partial/Rejected") -> Partial/Rejected | G9: 8340.2 | H9: =IF(ISERROR(VLOOKUP(A9,Report!A:D,4,FALSE)),"NOT FOUND",VLOOKUP(A9,Report!A:D,4,FALSE)) -> NOT FOUND | I9: 45869 | K9: =MONTH(C9) -> 4 | L9: =YEAR(C9) -> 2025
A10: PCI26C000005 | C10: 45777 | D10: 142876 | E10: MAHAKUMBH MELA | F10: =IF((D10-G10)<10,"Accepted","Partial/Rejected") -> Accepted | G10: 142875.58 | H10: =IF(ISERROR(VLOOKUP(A10,Report!A:D,4,FALSE)),"NOT FOUND",VLOOKUP(A10,Report!A:D,4,FALSE)) -> NOT FOUND | I10: 45868 | K10: =MONTH(C10) -> 4 | L10: =YEAR(C10) -> 2025
A11: PCI26C000006 | C11: 45777 | D11: 8832 | E11: REMOTE SERVICE CAMP | F11: =IF((D11-G11)<10,"Accepted","Partial/Rejected") -> Partial/Rejected | G11: 8682.3 | H11: =IF(ISERROR(VLOOKUP(A11,Report!A:D,4,FALSE)),"NOT FOUND",VLOOKUP(A11,Report!A:D,4,FALSE)) -> NOT FOUND | I11: 45868 | K11: =MONTH(C11) -> 4 | L11: =YEAR(C11) -> 2025
A12: PCI26E000001 | C12: 45808 | D12: 7776 | E12: REMOTE SERVICE CAMP | F12: =IF((D12-G12)<10,"Accepted","Partial/Rejected") -> Partial/Rejected | G12: 7644.2 | H12: =IF(ISERROR(VLOOKUP(A12,Report!A:D,4,FALSE)),"NOT FOUND",VLOOKUP(A12,Report!A:D,4,FALSE)) -> NOT FOUND | I12: 45869 | K12: =MONTH(C12) -> 5 | L12: =YEAR(C12) -> 2025
A13: PCI26E000002 | C13: 45808 | D13: 8838 | E13: REMOTE SERVICE CAMP | F13: =IF((D13-G13)<10,"Accepted","Partial/Rejected") -> Partial/Rejected | G13: 8688.2 | H13: =IF(ISERROR(VLOOKUP(A13,Report!A:D,4,FALSE)),"NOT FOUND",VLOOKUP(A13,Report!A:D,4,FALSE)) -> NOT FOUND | I13: 45869 | K13: =MONTH(C13) -> 5 | L13: =YEAR(C13) -> 2025
A14: SCI26E000007 | C14: 45839 | D14: 159064 | E14: FREE SERVICE CLAIM | F14: =IF((D14-G14)<10,"Accepted","Partial/Rejected") -> Accepted | G14: =IF(ISERROR(VLOOKUP(A14,Report!A:D,3,FALSE)),"NOT FOUND",VLOOKUP(A14,Report!A:D,3,FALSE)) -> 159064 | H14: =IF(ISERROR(VLOOKUP(A14,Report!A:D,4,FALSE)),"NOT FOUND",VLOOKUP(A14,Report!A:D,4,FALSE)) -> 3750 | I14: =IF(ISERROR(VLOOKUP(A14,Report!A:D,2,FALSE)),"NOT FOUND",VLOOKUP(A14,Report!A:D,2,FALSE)) -> 21-Aug-25 | K14: =MONTH(C14) -> 7 | L14: =YEAR(C14) -> 2025
A15: SCI26E000008 | C15: 45839 | D15: 34751 | E15: PDI COUPON CLAIM | F15: =IF((D15-G15)<10,"Accepted","Partial/Rejected") -> Accepted | G15: =IF(ISERROR(VLOOKUP(A15,Report!A:D,3,FALSE)),"NOT FOUND",VLOOKUP(A15,Report!A:D,3,FALSE)) -> 34751 | H15: =IF(ISERROR(VLOOKUP(A15,Report!A:D,4,FALSE)),"NOT FOUND",VLOOKUP(A15,Report!A:D,4,FALSE)) -> 0 | I15: =IF(ISERROR(VLOOKUP(A15,Report!A:D,2,FALSE)),"NOT FOUND",VLOOKUP(A15,Report!A:D,2,FALSE)) -> 20-Aug-25 | K15: =MONTH(C15) -> 7 | L15: =YEAR(C15) -> 2025
A16: SCI26D000002 | C16: 45839 | D16: 1239 | E16: PDI COUPON CLAIM | F16: =IF((D16-G16)<10,"Accepted","Partial/Rejected") -> Accepted | G16: =IF(ISERROR(VLOOKUP(A16,Report!A:D,3,FALSE)),"NOT FOUND",VLOOKUP(A16,Report!A:D,3,FALSE)) -> 1239 | H16: =IF(ISERROR(VLOOKUP(A16,Report!A:D,4,FALSE)),"NOT FOUND",VLOOKUP(A16,Report!A:D,4,FALSE)) -> 0 | I16: =IF(ISERROR(VLOOKUP(A16,Report!A:D,2,FALSE)),"NOT FOUND",VLOOKUP(A16,Report!A:D,2,FALSE)) -> 13-Aug-25 | K16: =MONTH(C16) -> 7 | L16: =YEAR(C16) -> 2025
A17: WCI26E000011 | C17: 45839 | D17: 53 | E17: Warranty | F17: =IF((D17-G17)<10,"Accepted","Partial/Rejected") -> Accepted | G17: =IF(ISERROR(VLOOKUP(A17,Report!A:D,3,FALSE)),"NOT FOUND",VLOOKUP(A17,Report!A:D,3,FALSE)) -> 53.1 | H17: =IF(ISERROR(VLOOKUP(A17,Report!A:D,4,FALSE)),"NOT FOUND",VLOOKUP(A17,Report!A:D,4,FALSE)) -> 0 | I17: =IF(ISERROR(VLOOKUP(A17,Report!A:D,2,FALSE)),"NOT FOUND",VLOOKUP(A17,Report!A:D,2,FALSE)) -> 23-07-2025 | K17: =MONTH(C17) -> 7 | L17: =YEAR(C17) -> 2025
A18: WCI26E000012 | C18: 45839 | D18: 53 | E18: Warranty | F18: =IF((D18-G18)<10,"Accepted","Partial/Rejected") -> Accepted | G18: =IF(ISERROR(VLOOKUP(A18,Report!A:D,3,FALSE)),"NOT FOUND",VLOOKUP(A18,Report!A:D,3,FALSE)) -> 53.1 | H18: =IF(ISERROR(VLOOKUP(A18,Report!A:D,4,FALSE)),"NOT FOUND",VLOOKUP(A18,Report!A:D,4,FALSE)) -> 0 | I18: =IF(ISERROR(VLOOKUP(A18,Report!A:D,2,FALSE)),"NOT FOUND",VLOOKUP(A18,Report!A:D,2,FALSE)) -> 23-07-2025 | K18: =MONTH(C18) -> 7 | L18: =YEAR(C18) -> 2025
A19: WCI26E000013 | C19: 45839 | D19: 53 | E19: Warranty | F19: =IF((D19-G19)<10,"Accepted","Partial/Rejected") -> Accepted | G19: =IF(ISERROR(VLOOKUP(A19,Report!A:D,3,FALSE)),"NOT FOUND",VLOOKUP(A19,Report!A:D,3,FALSE)) -> 53.1 | H19: =IF(ISERROR(VLOOKUP(A19,Report!A:D,4,FALSE)),"NOT FOUND",VLOOKUP(A19,Report!A:D,4,FALSE)) -> 0 | I19: =IF(ISERROR(VLOOKUP(A19,Report!A:D,2,FALSE)),"NOT FOUND",VLOOKUP(A19,Report!A:D,2,FALSE)) -> 23-07-2025 | K19: =MONTH(C19) -> 7 | L19: =YEAR(C19) -> 2025
A20: WCI26E000014 | C20: 45839 | D20: 53 | E20: Warranty | F20: =IF((D20-G20)<10,"Accepted","Partial/Rejected") -> Accepted | G20: =IF(ISERROR(VLOOKUP(A20,Report!A:D,3,FALSE)),"NOT FOUND",VLOOKUP(A20,Report!A:D,3,FALSE)) -> 53.1 | H20: =IF(ISERROR(VLOOKUP(A20,Report!A:D,4,FALSE)),"NOT FOUND",VLOOKUP(A20,Report!A:D,4,FALSE)) -> 0 | I20: =IF(ISERROR(VLOOKUP(A20,Report!A:D,2,FALSE)),"NOT FOUND",VLOOKUP(A20,Report!A:D,2,FALSE)) -> 23-07-2025 | K20: =MONTH(C20) -> 7 | L20: =YEAR(C20) -> 2025
A21: WCI26E000015 | C21: 45839 | D21: 53 | E21: Warranty | F21: =IF((D21-G21)<10,"Accepted","Partial/Rejected") -> Accepted | G21: =IF(ISERROR(VLOOKUP(A21,Report!A:D,3,FALSE)),"NOT FOUND",VLOOKUP(A21,Report!A:D,3,FALSE)) -> 53.1 | H21: =IF(ISERROR(VLOOKUP(A21,Report!A:D,4,FALSE)),"NOT FOUND",VLOOKUP(A21,Report!A:D,4,FALSE)) -> 0 | I21: =IF(ISERROR(VLOOKUP(A21,Report!A:D,2,FALSE)),"NOT FOUND",VLOOKUP(A21,Report!A:D,2,FALSE)) -> 23-07-2025 | K21: =MONTH(C21) -> 7 | L21: =YEAR(C21) -> 2025
A22: WCI26E000016 | C22: 45839 | D22: 53 | E22: Warranty | F22: =IF((D22-G22)<10,"Accepted","Partial/Rejected") -> Accepted | G22: =IF(ISERROR(VLOOKUP(A22,Report!A:D,3,FALSE)),"NOT FOUND",VLOOKUP(A22,Report!A:D,3,FALSE)) -> 53.1 | H22: =IF(ISERROR(VLOOKUP(A22,Report!A:D,4,FALSE)),"NOT FOUND",VLOOKUP(A22,Report!A:D,4,FALSE)) -> 0 | I22: =IF(ISERROR(VLOOKUP(A22,Report!A:D,2,FALSE)),"NOT FOUND",VLOOKUP(A22,Report!A:D,2,FALSE)) -> 23-07-2025 | K22: =MONTH(C22) -> 7 | L22: =YEAR(C22) -> 2025
A23: WCI26E000017 | C23: 45839 | D23: 53 | E23: Warranty | F23: =IF((D23-G23)<10,"Accepted","Partial/Rejected") -> Accepted | G23: =IF(ISERROR(VLOOKUP(A23,Report!A:D,3,FALSE)),"NOT FOUND",VLOOKUP(A23,Report!A:D,3,FALSE)) -> 53.1 | H23: =IF(ISERROR(VLOOKUP(A23,Report!A:D,4,FALSE)),"NOT FOUND",VLOOKUP(A23,Report!A:D,4,FALSE)) -> 0 | I23: =IF(ISERROR(VLOOKUP(A23,Report!A:D,2,FALSE)),"NOT FOUND",VLOOKUP(A23,Report!A:D,2,FALSE)) -> 23-07-2025 | K23: =MONTH(C23) -> 7 | L23: =YEAR(C23) -> 2025
A24: WCI26E000018 | C24: 45839 | D24: 53 | E24: Warranty | F24: =IF((D24-G24)<10,"Accepted","Partial/Rejected") -> Accepted | G24: =IF(ISERROR(VLOOKUP(A24,Report!A:D,3,FALSE)),"NOT FOUND",VLOOKUP(A24,Report!A:D,3,FALSE)) -> 53.1 | H24: =IF(ISERROR(VLOOKUP(A24,Report!A:D,4,FALSE)),"NOT FOUND",VLOOKUP(A24,Report!A:D,4,FALSE)) -> 0 | I24: =IF(ISERROR(VLOOKUP(A24,Report!A:D,2,FALSE)),"NOT FOUND",VLOOKUP(A24,Report!A:D,2,FALSE)) -> 23-07-2025 | K24: =MONTH(C24) -> 7 | L24: =YEAR(C24) -> 2025
A25: WCI26E000019 | C25: 45839 | D25: 53 | E25: Warranty | F25: =IF((D25-G25)<10,"Accepted","Partial/Rejected") -> Accepted | G25: =IF(ISERROR(VLOOKUP(A25,Report!A:D,3,FALSE)),"NOT FOUND",VLOOKUP(A25,Report!A:D,3,FALSE)) -> 53.1 | H25: =IF(ISERROR(VLOOKUP(A25,Report!A:D,4,FALSE)),"NOT FOUND",VLOOKUP(A25,Report!A:D,4,FALSE)) -> 0 | I25: =IF(ISERROR(VLOOKUP(A25,Report!A:D,2,FALSE)),"NOT FOUND",VLOOKUP(A25,Report!A:D,2,FALSE)) -> 23-07-2025 | K25: =MONTH(C25) -> 7 | L25: =YEAR(C25) -> 2025
... A107: WCI26E000101 | C107: 45839 | D107: 62 | E107: Warranty | F107: =IF((D107-G107)<10,"Accepted","Partial/Rejected") -> Accepted | G107: =IF(ISERROR(VLOOKUP(A107,Report!A:D,3,FALSE)),"NOT FOUND",VLOOKUP(A107,Report!A:D,3,FALSE)) -> 61.95 | H107: =IF(ISERROR(VLOOKUP(A107,Report!A:D,4,FALSE)),"NOT FOUND",VLOOKUP(A107,Report!A:D,4,FALSE)) -> 0 | I107: =IF(ISERROR(VLOOKUP(A107,Report!A:D,2,FALSE)),"NOT FOUND",VLOOKUP(A107,Report!A:D,2,FALSE)) -> 31-07-2025 | K107: =MONTH(C107) -> 7 | L107: =YEAR(C107) -> 2025
A108: WCI26E000103 | B108: 360 | C108: 45869 | D108: 88274 | E108: Warranty | F108: =IF((D108-G108)<10,"Accepted","Partial/Rejected") -> Accepted | G108: =IF(ISERROR(VLOOKUP(A108,Report!A:D,3,FALSE)),"NOT FOUND",VLOOKUP(A108,Report!A:D,3,FALSE)) -> 88274.19 | H108: =IF(ISERROR(VLOOKUP(A108,Report!A:D,4,FALSE)),"NOT FOUND",VLOOKUP(A108,Report!A:D,4,FALSE)) -> 0 | I108: =IF(ISERROR(VLOOKUP(A108,Report!A:D,2,FALSE)),"NOT FOUND",VLOOKUP(A108,Report!A:D,2,FALSE)) -> 30-09-2025 | K108: =MONTH(C108) -> 7 | L108: =YEAR(C108) -> 2025
A109: WCI26C000003 | B109: 361 | C109: 45777 | D109: 4471 | E109: Warranty | F109: =IF((D109-G109)<10,"Accepted","Partial/Rejected") -> Accepted | G109: =IF(ISERROR(VLOOKUP(A109,Report!A:D,3,FALSE)),"NOT FOUND",VLOOKUP(A109,Report!A:D,3,FALSE)) -> 4470.63 | H109: =IF(ISERROR(VLOOKUP(A109,Report!A:D,4,FALSE)),"NOT FOUND",VLOOKUP(A109,Report!A:D,4,FALSE)) -> 0 | I109: =IF(ISERROR(VLOOKUP(A109,Report!A:D,2,FALSE)),"NOT FOUND",VLOOKUP(A109,Report!A:D,2,FALSE)) -> 29-05-2025 | K109: =MONTH(C109) -> 4 | L109: =YEAR(C109) -> 2025
A110: WCI26C000004 | B110: 362 | C110: 45777 | D110: 2765 | E110: Warranty | F110: =IF((D110-G110)<10,"Accepted","Partial/Rejected") -> Accepted | G110: =IF(ISERROR(VLOOKUP(A110,Report!A:D,3,FALSE)),"NOT FOUND",VLOOKUP(A110,Report!A:D,3,FALSE)) -> 2765.42 | H110: =IF(ISERROR(VLOOKUP(A110,Report!A:D,4,FALSE)),"NOT FOUND",VLOOKUP(A110,Report!A:D,4,FALSE)) -> 0 | I110: =IF(ISERROR(VLOOKUP(A110,Report!A:D,2,FALSE)),"NOT FOUND",VLOOKUP(A110,Report!A:D,2,FALSE)) -> 29-05-2025 | K110: =MONTH(C110) -> 4 | L110: =YEAR(C110) -> 2025
A111: WCI26C000005 | B111: 363 | C111: 45777 | D111: 3419 | E111: Warranty | F111: =IF((D111-G111)<10,"Accepted","Partial/Rejected") -> Accepted | G111: =IF(ISERROR(VLOOKUP(A111,Report!A:D,3,FALSE)),"NOT FOUND",VLOOKUP(A111,Report!A:D,3,FALSE)) -> 3419.35 | H111: =IF(ISERROR(VLOOKUP(A111,Report!A:D,4,FALSE)),"NOT FOUND",VLOOKUP(A111,Report!A:D,4,FALSE)) -> 0 | I111: =IF(ISERROR(VLOOKUP(A111,Report!A:D,2,FALSE)),"NOT FOUND",VLOOKUP(A111,Report!A:D,2,FALSE)) -> 29-05-2025 | K111: =MONTH(C111) -> 4 | L111: =YEAR(C111) -> 2025
A112: WCI26C000006 | B112: 364 | C112: 45777 | D112: 2916 | E112: Warranty | F112: =IF((D112-G112)<10,"Accepted","Partial/Rejected") -> Accepted | G112: =IF(ISERROR(VLOOKUP(A112,Report!A:D,3,FALSE)),"NOT FOUND",VLOOKUP(A112,Report!A:D,3,FALSE)) -> 2916.44 | H112: =IF(ISERROR(VLOOKUP(A112,Report!A:D,4,FALSE)),"NOT FOUND",VLOOKUP(A112,Report!A:D,4,FALSE)) -> 0 | I112: =IF(ISERROR(VLOOKUP(A112,Report!A:D,2,FALSE)),"NOT FOUND",VLOOKUP(A112,Report!A:D,2,FALSE)) -> 29-05-2025 | K112: =MONTH(C112) -> 4 | L112: =YEAR(C112) -> 2025
A113: WCI26C000007 | B113: 365 | C113: 45777 | D113: 8418 | E113: Warranty | F113: =IF((D113-G113)<10,"Accepted","Partial/Rejected") -> Accepted | G113: =IF(ISERROR(VLOOKUP(A113,Report!A:D,3,FALSE)),"NOT FOUND",VLOOKUP(A113,Report!A:D,3,FALSE)) -> 8418.35 | H113: =IF(ISERROR(VLOOKUP(A113,Report!A:D,4,FALSE)),"NOT FOUND",VLOOKUP(A113,Report!A:D,4,FALSE)) -> 0 | I113: =IF(ISERROR(VLOOKUP(A113,Report!A:D,2,FALSE)),"NOT FOUND",VLOOKUP(A113,Report!A:D,2,FALSE)) -> 29-05-2025 | K113: =MONTH(C113) -> 4 | L113: =YEAR(C113) -> 2025
A114: CANCELL | B114: 366 | F114: =IF((D114-G114)<10,"Accepted","Partial/Rejected") -> #VALUE! | G114: =IF(ISERROR(VLOOKUP(A114,Report!A:D,3,FALSE)),"NOT FOUND",VLOOKUP(A114,Report!A:D,3,FALSE)) -> NOT FOUND | H114: =IF(ISERROR(VLOOKUP(A114,Report!A:D,4,FALSE)),"NOT FOUND",VLOOKUP(A114,Report!A:D,4,FALSE)) -> NOT FOUND | I114: =IF(ISERROR(VLOOKUP(A114,Report!A:D,2,FALSE)),"NOT FOUND",VLOOKUP(A114,Report!A:D,2,FALSE)) -> NOT FOUND | K114: =MONTH(C114) -> 1 | L114: =YEAR(C114) -> 1900
A115: WCI26C000008 | B115: 367 | C115: 45777 | D115: 1927 | E115: Warranty | F115: =IF((D115-G115)<10,"Accepted","Partial/Rejected") -> Accepted | G115: =IF(ISERROR(VLOOKUP(A115,Report!A:D,3,FALSE)),"NOT FOUND",VLOOKUP(A115,Report!A:D,3,FALSE)) -> 1926.94 | H115: =IF(ISERROR(VLOOKUP(A115,Report!A:D,4,FALSE)),"NOT FOUND",VLOOKUP(A115,Report!A:D,4,FALSE)) -> 0 | I115: =IF(ISERROR(VLOOKUP(A115,Report!A:D,2,FALSE)),"NOT FOUND",VLOOKUP(A115,Report!A:D,2,FALSE)) -> 29-05-2025 | K115: =MONTH(C115) -> 4 | L115: =YEAR(C115) -> 2025
B116: 368 | F116: =IF((D116-G116)<10,"Accepted","Partial/Rejected") -> #VALUE! | G116: =IF(ISERROR(VLOOKUP(A116,Report!A:D,3,FALSE)),"NOT FOUND",VLOOKUP(A116,Report!A:D,3,FALSE)) -> NOT FOUND | H116: =IF(ISERROR(VLOOKUP(A116,Report!A:D,4,FALSE)),"NOT FOUND",VLOOKUP(A116,Report!A:D,4,FALSE)) -> NOT FOUND | I116: =IF(ISERROR(VLOOKUP(A116,Report!A:D,2,FALSE)),"NOT FOUND",VLOOKUP(A116,Report!A:D,2,FALSE)) -> NOT FOUND | J116: WORNG CLAIM/NOT WARRANTY/PARTS BILLING OUTSIDE | K116: =MONTH(C116) -> 1 | L116: =YEAR(C116) -> 1900
A117: WCI26C000009 | B117: 369 | C117: 45777 | D117: 11953 | E117: Warranty | F117: =IF((D117-G117)<10,"Accepted","Partial/Rejected") -> Accepted | G117: =IF(ISERROR(VLOOKUP(A117,Report!A:D,3,FALSE)),"NOT FOUND",VLOOKUP(A117,Report!A:D,3,FALSE)) -> 11952.71 | H117: =IF(ISERROR(VLOOKUP(A117,Report!A:D,4,FALSE)),"NOT FOUND",VLOOKUP(A117,Report!A:D,4,FALSE)) -> 0 | I117: =IF(ISERROR(VLOOKUP(A117,Report!A:D,2,FALSE)),"NOT FOUND",VLOOKUP(A117,Report!A:D,2,FALSE)) -> 29-05-2025 | K117: =MONTH(C117) -> 4 | L117: =YEAR(C117) -> 2025
A118: WCI26E000002 | B118: 370 | C118: 45808 | D118: 689 | E118: Warranty | F118: =IF((D118-G118)<10,"Accepted","Partial/Rejected") -> Accepted | G118: =IF(ISERROR(VLOOKUP(A118,Report!A:D,3,FALSE)),"NOT FOUND",VLOOKUP(A118,Report!A:D,3,FALSE)) -> 689.36 | H118: =IF(ISERROR(VLOOKUP(A118,Report!A:D,4,FALSE)),"NOT FOUND",VLOOKUP(A118,Report!A:D,4,FALSE)) -> 0 | I118: =IF(ISERROR(VLOOKUP(A118,Report!A:D,2,FALSE)),"NOT FOUND",VLOOKUP(A118,Report!A:D,2,FALSE)) -> 23-07-2025 | K118: =MONTH(C118) -> 5 | L118: =YEAR(C118) -> 2025
A119: WCI26E000003 | B119: 371 | C119: 45808 | D119: 7636 | E119: Warranty | F119: =IF((D119-G119)<10,"Accepted","Partial/Rejected") -> Accepted | G119: =IF(ISERROR(VLOOKUP(A119,Report!A:D,3,FALSE)),"NOT FOUND",VLOOKUP(A119,Report!A:D,3,FALSE)) -> 7635.58 | H119: =IF(ISERROR(VLOOKUP(A119,Report!A:D,4,FALSE)),"NOT FOUND",VLOOKUP(A119,Report!A:D,4,FALSE)) -> 0 | I119: =IF(ISERROR(VLOOKUP(A119,Report!A:D,2,FALSE)),"NOT FOUND",VLOOKUP(A119,Report!A:D,2,FALSE)) -> 23-07-2025 | K119: =MONTH(C119) -> 5 | L119: =YEAR(C119) -> 2025
A120: WCI26E000003 | B120: 371 | C120: 45808 | D120: 7636 | E120: Warranty | F120: =IF((D120-G120)<10,"Accepted","Partial/Rejected") -> Accepted | G120: =IF(ISERROR(VLOOKUP(A120,Report!A:D,3,FALSE)),"NOT FOUND",VLOOKUP(A120,Report!A:D,3,FALSE)) -> 7635.58 | H120: =IF(ISERROR(VLOOKUP(A120,Report!A:D,4,FALSE)),"NOT FOUND",VLOOKUP(A120,Report!A:D,4,FALSE)) -> 0 | I120: =IF(ISERROR(VLOOKUP(A120,Report!A:D,2,FALSE)),"NOT FOUND",VLOOKUP(A120,Report!A:D,2,FALSE)) -> 23-07-2025 | K120: =MONTH(C120) -> 5 | L120: =YEAR(C120) -> 2025
A121: WCI26E000004 | B121: 372 | C121: 45808 | D121: 3419 | E121: Warranty | F121: =IF((D121-G121)<10,"Accepted","Partial/Rejected") -> Accepted | G121: =IF(ISERROR(VLOOKUP(A121,Report!A:D,3,FALSE)),"NOT FOUND",VLOOKUP(A121,Report!A:D,3,FALSE)) -> 3419.35 | H121: =IF(ISERROR(VLOOKUP(A121,Report!A:D,4,FALSE)),"NOT FOUND",VLOOKUP(A121,Report!A:D,4,FALSE)) -> 0 | I121: =IF(ISERROR(VLOOKUP(A121,Report!A:D,2,FALSE)),"NOT FOUND",VLOOKUP(A121,Report!A:D,2,FALSE)) -> 23-07-2025 | K121: =MONTH(C121) -> 5 | L121: =YEAR(C121) -> 2025
...

Sheet Claim Summary
A2: Claim Month | B2: (All)
A4: Claim Year | B4: Type of Claim (PDI/Warranty/Service Campaign/Breakdown/Others) | C4: Sum of Invoice Value | D4: Sum of Claim Passed Amount | E4: Sum of Rejected Amount | F4: Percentage of rejection
A5: 2025 | B5: CSI CLAIM | C5: 17700 | D5: 0 | E5: 0
B6: FREE SERVICE CLAIM | C6: 1059522 | D6: 1059522 | E6: 58690 | F6: =E6/D6 -> 0.055392904
B7: MAHAKUMBH MELA | C7: 142876 | D7: 142875.58 | E7: 0 | F7: =E7/D7 -> 0
B8: PDI COUPON CLAIM | C8: 247741 | D8: 247741 | E8: 0 | F8: =E8/D8 -> 0
B9: REMOTE SERVICE CAMP | C9: 82203.8 | D9: 58075.9 | E9: 0 | F9: =E9/D9 -> 0
B10: Warranty | C10: 899680 | D10: 843824.7 | E10: 74756.99 | F10: =E10/D10 -> 0.088593034
A11: 2025 Total | C11: 2449722.8 | D11: 2352039.2 | E11: 133446.99 | F11: =E11/D11 -> 0.056736721
A12: 2026 | B12: CSI CLAIM | C12: 94477.31 | D12: 0 | E12: 0 | F12: =E12/D12 -> #DIV/0!
B13: FREE SERVICE CLAIM | C13: 135877 | D13: 131924 | E13: 16860 | F13: =E13/D13 -> 0.12780086
B14: PDI COUPON CLAIM | C14: 29205 | D14: 0 | E14: 0 | F14: =E14/D14 -> #DIV/0!
B15: Warranty | C15: 51753 | D15: 50021.45 | E15: 0 | F15: =E15/D15 -> 0
A16: 2026 Total | C16: 311312.31 | D16: 181945.45 | E16: 16860 | F16: =E16/D16 -> 0.092665137
A17: Grand Total | C17: 2761035.1 | D17: 2533984.6 | E17: 150306.99

Sheet PDI report
A1: Sr. No. | B1: Zone | C1: State | D1: Dealer Code | E1: Dealer Name | F1: Dealer Location | G1: Scheme | H1: Sale Date | I1: Sale Kms/Hrs. | J1: Coupon No. | K1: Chassis No. | L1: Engine No. | M1: Vehicle Type | N1: Invoice No. | O1: INVOICE_DATE | P1: Settlement Date | Q1: Invoice Amount | R1: Credit Amount | S1: GST Amount | T1: Net Amount | U1: Credit Note No. | V1: Credit Note Date | W1: Debit Amount | X1: Debit Note No. | Y1: Debit Note Date | Z1: FI Doc No Credit | AA1: FI Doc No Debit | AB1: Rejection Code | AC1: Rejection Desc. | AD1: Rejection Percent
A2: 1 | B2: NORTH | C2: UTTAR PRADESH | D2: 7134 | E2: M/S GOENKA AUTO PRIVATE LIMITED. | F2: VARANASI | G2: S | H2: 30-Mar-25 | I2: 1165 | J2: 00327606 | K2: MC1D4DBA3SP107505 | L2: D72019127 | M2: TRAX | N2: SCI25C000040 | O2: 19-Mar-2025 | P2: 23-Apr-25 | Q2: 1150 | R2: 1150 | S2: 207 | T2: 1357 | U2: 620984 | V2: 03-Jun-25 | W2: 0 | X2: 32237 | Y2: 03-Jun-25
A3: 2 | B3: NORTH | C3: UTTAR PRADESH | D3: 7134 | E3: M/S GOENKA AUTO PRIVATE LIMITED. | F3: VARANASI | G3: S | H3: 29-Mar-25 | I3: 1165 | J3: 00781693 | K3: MC1E4EFA1RP013332 | L3: D71057281 | M3: T-1 | N3: SCI25C000040 | O3: 18-Jul-2024 | P3: 23-Apr-25 | Q3: 1150 | R3: 1150 | S3: 207 | T3: 1357 | U3: 620984 | V3: 03-Jun-25 | W3: 0 | X3: 32237 | Y3: 03-Jun-25
A4: 3 | B4: NORTH | C4: UTTAR PRADESH | D4: 7134 | E4: M/S GOENKA AUTO PRIVATE LIMITED. | F4: VARANASI | G4: S | H4: 30-Mar-25 | I4: 1165 | J4: 00327605 | K4: MC1D4DBA2SP107513 | L4: D72019118 | M4: TRAX | N4: SCI25C000040 | O4: 19-Mar-2025 | P4: 23-Apr-25 | Q4: 1150 | R4: 1150 | S4: 207 | T4: 1357 | U4: 620984 | V4: 03-Jun-25 | W4: 0 | X4: 32237 | Y4: 03-Jun-25
A5: 4 | B5: NORTH | C5: UTTAR PRADESH | D5: 7134 | E5: M/S GOENKA AUTO PRIVATE LIMITED. | F5: VARANASI | G5: S | H5: 13-Mar-25 | I5: 1165 | J5: 00797216 | K5: MC1E4DAA1SP055796 | L5: D71068659 | M5: T-1 | N5: SCI25C000040 | O5: 31-Jan-2025 | P5: 23-Apr-25 | Q5: 1150 | R5: 1150 | S5: 207 | T5: 1357 | U5: 620984 | V5: 03-Jun-25 | W5: 0 | X5: 32237 | Y5: 03-Jun-25
A6: 5 | B6: NORTH | C6: UTTAR PRADESH | D6: 7134 | E6: M/S GOENKA AUTO PRIVATE LIMITED. | F6: VARANASI | G6: S | H6: 30-Mar-25 | I6: 1165 | J6: 00327607 | K6: MC1D4DBA8SP107483 | L6: D72019091 | M6: TRAX | N6: SCI25C000040 | O6: 19-Mar-2025 | P6: 23-Apr-25 | Q6: 1150 | R6: 1150 | S6: 207 | T6: 1357 | U6: 620984 | V6: 03-Jun-25 | W6: 0 | X6: 32237 | Y6: 03-Jun-25
A7: 6 | B7: NORTH | C7: UTTAR PRADESH | D7: 7134 | E7: M/S GOENKA AUTO PRIVATE LIMITED. | F7: VARANASI | G7: S | H7: 29-Mar-25 | I7: 1165 | J7: 00006960 | K7: MC1M4ACA2SP003858 | L7: D71076103 | M7: T1N | N7: SCI25C000040 | O7: 25-Mar-2025 | P7: 23-Apr-25 | Q7: 1500 | R7: 1500 | S7: 270 | T7: 1770 | U7: 620984 | V7: 03-Jun-25 | W7: 0 | X7: 32237 | Y7: 03-Jun-25
A8: 7 | B8: NORTH | C8: UTTAR PRADESH | D8: 7134 | E8: M/S GOENKA AUTO PRIVATE LIMITED. | F8: VARANASI | G8: S | H8: 06-Mar-25 | I8: 1165 | J8: 00327885 | K8: MC1D4DAA9SP107140 | L8: D72018775 | M8: TRAX | N8: SCI25C000040 | O8: 15-Feb-2025 | P8: 23-Apr-25 | Q8: 1150 | R8: 1150 | S8: 207 | T8: 1357 | U8: 620984 | V8: 03-Jun-25 | W8: 0 | X8: 32237 | Y8: 03-Jun-25
A9: 8 | B9: NORTH | C9: UTTAR PRADESH | D9: 7134 | E9: M/S GOENKA AUTO PRIVATE LIMITED. | F9: VARANASI | G9: S | H9: 17-Mar-25 | I9: 1165 | J9: 00784362 | K9: MC1E4FAA3SP022049 | L9: D71067216 | M9: T26 | N9: SCI25C000040 | O9: 16-Jan-2025 | P9: 23-Apr-25 | Q9: 1150 | R9: 1150 | S9: 207 | T9: 1357 | U9: 620984 | V9: 03-Jun-25 | W9: 0 | X9: 32237 | Y9: 03-Jun-25
A10: 9 | B10: NORTH | C10: UTTAR PRADESH | D10: 7134 | E10: M/S GOENKA AUTO PRIVATE LIMITED. | F10: VARANASI | G10: S | H10: 29-Mar-25 | I10: 1160 | J10: 00784698 | K10: MC1E4FBA0SP022668 | L10: D71071710 | M10: T26 | N10: SCI25C000040 | O10: 12-Mar-2025 | P10: 23-Apr-25 | Q10: 1150 | R10: 1150 | S10: 207 | T10: 1357 | U10: 620984 | V10: 03-Jun-25 | W10: 0 | X10: 32237 | Y10: 03-Jun-25
A11: 10 | B11: NORTH | C11: UTTAR PRADESH | D11: 7134 | E11: M/S GOENKA AUTO PRIVATE LIMITED. | F11: VARANASI | G11: S | H11: 21-Mar-25 | I11: 1165 | J11: 00784731 | K11: MC1E4FAA2SP022334 | L11: D71069755 | M11: T26 | N11: SCI25C000040 | O11: 27-Feb-2025 | P11: 23-Apr-25 | Q11: 1150 | R11: 1150 | S11: 207 | T11: 1357 | U11: 620984 | V11: 03-Jun-25 | W11: 0 | X11: 32237 | Y11: 03-Jun-25
A12: 11 | B12: NORTH | C12: UTTAR PRADESH | D12: 7134 | E12: M/S GOENKA AUTO PRIVATE LIMITED. | F12: VARANASI | G12: S | H12: 24-Mar-25 | I12: 1165 | J12: 00797196 | K12: MC1E4DBA0SP055996 | L12: D71071829 | M12: T-1 | N12: SCI25C000040 | O12: 05-Mar-2025 | P12: 23-Apr-25 | Q12: 1150 | R12: 1150 | S12: 207 | T12: 1357 | U12: 620984 | V12: 03-Jun-25 | W12: 0 | X12: 32237 | Y12: 03-Jun-25
A13: 12 | B13: NORTH | C13: UTTAR PRADESH | D13: 7134 | E13: M/S GOENKA AUTO PRIVATE LIMITED. | F13: VARANASI | G13: S | H13: 18-Mar-25 | I13: 1165 | J13: 00327338 | K13: MC1D4DBA4SP107271 | L13: D72018874 | M13: TRAX | N13: SCI25C000040 | O13: 26-Feb-2025 | P13: 23-Apr-25 | Q13: 1150 | R13: 1150 | S13: 207 | T13: 1357 | U13: 620984 | V13: 03-Jun-25 | W13: 0 | X13: 32237 | Y13: 03-Jun-25
... A19: 18 | B19: NORTH | C19: UTTAR PRADESH | D19: 7134 | E19: M/S GOENKA AUTO PRIVATE LIMITED. | F19: VARANASI | G19: S | H19: 29-Mar-25 | I19: 1165 | J19: 00788228 | K19: MC1L4BGA5SP000738 | L19: D71058742 | M19: T3 | N19: SCI25C000040 | O19: 04-Oct-2024 | P19: 23-Apr-25 | Q19: 1150 | R19: 1150 | S19: 207 | T19: 1357 | U19: 620984 | V19: 03-Jun-25 | W19: 0 | X19: 32237 | Y19: 03-Jun-25
A20: 19 | B20: NORTH | C20: UTTAR PRADESH | D20: 7134 | E20: M/S GOENKA AUTO PRIVATE LIMITED. | F20: VARANASI | G20: S | H20: 31-Mar-25 | I20: 1165 | J20: 00789040 | K20: MC1E4FCA2SP023142 | L20: D71076641 | M20: T26 | N20: SCI25C000040 | O20: 29-Mar-2025 | P20: 23-Apr-25 | Q20: 1150 | R20: 0 | S20: 207 | T20: 1357 | U20: 620984 | V20: 03-Jun-25 | W20: 1150 | X20: 32237 | Y20: 03-Jun-25 | AB20: 022 | AC20: PDI COUPON HARD COPY NOT RECEIVED | AD20: 100
A21: 20 | B21: NORTH | C21: UTTAR PRADESH | D21: 7134 | E21: M/S GOENKA AUTO PRIVATE LIMITED. | F21: VARANASI | G21: S | H21: 31-Mar-25 | I21: 1165 | J21: 00796243 | K21: MC1E5DAA6SP000614 | L21: D73001641 | M21: T-1 | N21: SCI25C000040 | O21: 24-Jan-2025 | P21: 23-Apr-25 | Q21: 1150 | R21: 0 | S21: 207 | T21: 1357 | U21: 620984 | V21: 03-Jun-25 | W21: 1150 | X21: 32237 | Y21: 03-Jun-25 | AB21: 022 | AC21: PDI COUPON HARD COPY NOT RECEIVED | AD21: 100
A22: 21 | B22: NORTH | C22: UTTAR PRADESH | D22: 7134 | E22: M/S GOENKA AUTO PRIVATE LIMITED. | F22: VARANASI | G22: S | H22: 29-Mar-25 | I22: 1165 | J22: 00327424 | K22: MC1D4DCA3SP107776 | L22: D72019387 | M22: TRAX | N22: SCI25C000040 | O22: 07-Mar-2025 | P22: 23-Apr-25 | Q22: 1150 | R22: 1150 | S22: 207 | T22: 1357 | U22: 620984 | V22: 03-Jun-25 | W22: 0 | X22: 32237 | Y22: 03-Jun-25
A23: 22 | B23: NORTH | C23: UTTAR PRADESH | D23: 7134 | E23: M/S GOENKA AUTO PRIVATE LIMITED. | F23: VARANASI | G23: S | H23: 21-Mar-25 | I23: 1165 | J23: 00327821 | K23: MC1D4DAA3SP107117 | L23: D72018790 | M23: TRAX | N23: SCI25C000040 | O23: 19-Feb-2025 | P23: 23-Apr-25 | Q23: 1150 | R23: 1150 | S23: 207 | T23: 1357 | U23: 620984 | V23: 03-Jun-25 | W23: 0 | X23: 32237 | Y23: 03-Jun-25
A24: 23 | B24: NORTH | C24: UTTAR PRADESH | D24: 7134 | E24: M/S GOENKA AUTO PRIVATE LIMITED. | F24: VARANASI | G24: S | H24: 25-Mar-25 | I24: 1165 | J24: 00327825 | K24: MC1D4DAA4SP107109 | L24: D72018744 | M24: TRAX | N24: SCI25C000040 | O24: 19-Feb-2025 | P24: 23-Apr-25 | Q24: 1150 | R24: 1150 | S24: 207 | T24: 1357 | U24: 620984 | V24: 03-Jun-25 | W24: 0 | X24: 32237 | Y24: 03-Jun-25
A25: 24 | B25: NORTH | C25: UTTAR PRADESH | D25: 7134 | E25: M/S GOENKA AUTO PRIVATE LIMITED. | F25: VARANASI | G25: S | H25: 22-Mar-25 | I25: 1165 | J25: 00328028 | K25: MC1D1DBA7SP001616 | L25: D72018969 | M25: TRAX | N25: SCI25C000040 | O25: 11-Mar-2025 | P25: 23-Apr-25 | Q25: 1150 | R25: 1150 | S25: 207 | T25: 1357 | U25: 620984 | V25: 03-Jun-25 | W25: 0 | X25: 32237 | Y25: 03-Jun-25
A26: 25 | B26: NORTH | C26: UTTAR PRADESH | D26: 7134 | E26: M/S GOENKA AUTO PRIVATE LIMITED. | F26: VARANASI | G26: S | H26: 21-Mar-25 | I26: 1165 | J26: 00795278 | K26: MC1E4DBA8SP056040 | L26: D71072655 | M26: T-1 | N26: SCI25C000040 | O26: 07-Mar-2025 | P26: 23-Apr-25 | Q26: 1150 | R26: 1150 | S26: 207 | T26: 1357 | U26: 620984 | V26: 03-Jun-25 | W26: 0 | X26: 32237 | Y26: 03-Jun-25
A27: 26 | B27: NORTH | C27: UTTAR PRADESH | D27: 7134 | E27: M/S GOENKA AUTO PRIVATE LIMITED. | F27: VARANASI | G27: S | H27: 25-Mar-25 | I27: 1165 | J27: 00785188 | K27: MC1E4EBA7SP015419 | L27: D71073629 | M27: T-1 | N27: SCI25C000040 | O27: 28-Feb-2025 | P27: 23-Apr-25 | Q27: 1150 | R27: 1150 | S27: 207 | T27: 1357 | U27: 620984 | V27: 03-Jun-25 | W27: 0 | X27: 32237 | Y27: 03-Jun-25
A28: 27 | B28: NORTH | C28: UTTAR PRADESH | D28: 7134 | E28: M/S GOENKA AUTO PRIVATE LIMITED. | F28: VARANASI | G28: S | H28: 30-Mar-25 | I28: 1165 | J28: 00796641 | K28: MC1E4DCA0SP056225 | L28: D71074854 | M28: T-1 | N28: SCI25C000040 | O28: 19-Mar-2025 | P28: 23-Apr-25 | Q28: 1150 | R28: 1150 | S28: 207 | T28: 1357 | U28: 620984 | V28: 03-Jun-25 | W28: 0 | X28: 32237 | Y28: 03-Jun-25
A29: 28 | B29: NORTH | C29: UTTAR PRADESH | D29: 7134 | E29: M/S GOENKA AUTO PRIVATE LIMITED. | F29: VARANASI | G29: S | H29: 31-Mar-25 | I29: 1165 | J29: 00327370 | K29: MC1D4DCA0SP107864 | L29: D72019478 | M29: TRAX | N29: SCI25C000040 | O29: 19-Mar-2025 | P29: 23-Apr-25 | Q29: 1150 | R29: 1150 | S29: 207 | T29: 1357 | U29: 620984 | V29: 03-Jun-25 | W29: 0 | X29: 32237 | Y29: 03-Jun-25
A30: 29 | B30: NORTH | C30: UTTAR PRADESH | D30: 7134 | E30: M/S GOENKA AUTO PRIVATE LIMITED. | F30: VARANASI | G30: S | H30: 08-Mar-25 | I30: 1165 | J30: 00327879 | K30: MC1D4DAA2SP107111 | L30: D72018740 | M30: TRAX | N30: SCI25C000040 | O30: 15-Feb-2025 | P30: 23-Apr-25 | Q30: 1150 | R30: 1150 | S30: 207 | T30: 1357 | U30: 620984 | V30: 03-Jun-25 | W30: 0 | X30: 32237 | Y30: 03-Jun-25
A31: 30 | B31: NORTH | C31: UTTAR PRADESH | D31: 7134 | E31: M/S GOENKA AUTO PRIVATE LIMITED. | F31: VARANASI | G31: S | H31: 30-Mar-25 | I31: 1165 | J31: 00796637 | K31: MC1E4DCA4SP056163 | L31: D71074480 | M31: T-1 | N31: SCI25C000040 | O31: 19-Mar-2025 | P31: 23-Apr-25 | Q31: 1150 | R31: 1150 | S31: 207 | T31: 1357 | U31: 620984 | V31: 03-Jun-25 | W31: 0 | X31: 32237 | Y31: 03-Jun-25
A32: 31 | B32: NORTH | C32: UTTAR PRADESH | D32: 7134 | E32: M/S GOENKA AUTO PRIVATE LIMITED. | F32: VARANASI | G32: S | H32: 26-Mar-25 | I32: 1165 | J32: 00801400 | K32: MC1E4DCA0SP056435 | L32: D71075442 | M32: T-1 | N32: SCI25C000040 | O32: 17-Mar-2025 | P32: 23-Apr-25 | Q32: 1150 | R32: 1150 | S32: 207 | T32: 1357 | U32: 620984 | V32: 03-Jun-25 | W32: 0 | X32: 32237 | Y32: 03-Jun-25
A33: 32 | B33: NORTH | C33: UTTAR PRADESH | D33: 7134 | E33: M/S GOENKA AUTO PRIVATE LIMITED. | F33: VARANASI | G33: S | H33: 11-Mar-25 | I33: 1165 | J33: 00797921 | K33: MC1E4DAA2SP055855 | L33: D71070759 | M33: T-1 | N33: SCI25C000040 | O33: 19-Feb-2025 | P33: 23-Apr-25 | Q33: 1150 | R33: 1150 | S33: 207 | T33: 1357 | U33: 620984 | V33: 03-Jun-25 | W33: 0 | X33: 32237 | Y33: 03-Jun-25
... A40: 39 | B40: NORTH | C40: UTTAR PRADESH | D40: 7134 | E40: M/S GOENKA AUTO PRIVATE LIMITED. | F40: VARANASI | G40: S | H40: 21-Mar-25 | I40: 1165 | J40: 00798847 | K40: MC1E4DAA5SP055932 | L40: D71069296 | M40: T-1 | N40: SCI25C000040 | O40: 26-Feb-2025 | P40: 23-Apr-25 | Q40: 1150 | R40: 1150 | S40: 207 | T40: 1357 | U40: 620984 | V40: 03-Jun-25 | W40: 0 | X40: 32237 | Y40: 03-Jun-25
A41: 40 | B41: NORTH | C41: UTTAR PRADESH | D41: 7134 | E41: M/S GOENKA AUTO PRIVATE LIMITED. | F41: VARANASI | G41: S | H41: 05-Mar-25 | I41: 1165 | J41: 00795726 | K41: MC1E4DAA9SP055836 | L41: D71069019 | M41: T-1 | N41: SCI26E000001 | O41: 13-Feb-2025 | P41: 09-Jul-25 | Q41: 1150 | R41: 0 | S41: 207 | T41: 1357 | U41: 621504 | V41: 19-Aug-25 | W41: 1150 | X41: 32757 | Y41: 19-Aug-25 | AB41: 010 | AC41: LATE SUBMISSION | AD41: 100
A42: 41 | B42: NORTH | C42: UTTAR PRADESH | D42: 7134 | E42: M/S GOENKA AUTO PRIVATE LIMITED. | F42: VARANASI | G42: S | H42: 27-Feb-25 | I42: 1165 | J42: 00785025 | K42: MC1E4EBA2SP015313 | L42: D71072545 | M42: T-1 | N42: SCI26E000001 | O42: 25-Feb-2025 | P42: 09-Jul-25 | Q42: 1150 | R42: 0 | S42: 207 | T42: 1357 | U42: 621504 | V42: 19-Aug-25 | W42: 1150 | X42: 32757 | Y42: 19-Aug-25 | AB42: 010 | AC42: LATE SUBMISSION | AD42: 100
A43: 42 | B43: NORTH | C43: UTTAR PRADESH | D43: 7134 | E43: M/S GOENKA AUTO PRIVATE LIMITED. | F43: VARANASI | G43: S | H43: 07-Mar-25 | I43: 1165 | J43: 00789309 | K43: MC1E4FLA7SP021807 | L43: D71066302 | M43: T26 | N43: SCI26E000001 | O43: 25-Dec-2024 | P43: 09-Jul-25 | Q43: 1150 | R43: 0 | S43: 207 | T43: 1357 | U43: 621504 | V43: 19-Aug-25 | W43: 1150 | X43: 32757 | Y43: 19-Aug-25 | AB43: 010 | AC43: LATE SUBMISSION | AD43: 100
A44: 43 | B44: NORTH | C44: UTTAR PRADESH | D44: 7134 | E44: M/S GOENKA AUTO PRIVATE LIMITED. | F44: VARANASI | G44: S | H44: 13-Mar-25 | I44: 1165 | J44: 00006118 | K44: MC1M4ALA8SP002956 | L44: D71066667 | M44: T1N | N44: SCI26E000001 | O44: 31-Dec-2024 | P44: 09-Jul-25 | Q44: 1500 | R44: 0 | S44: 270 | T44: 1770 | U44: 621504 | V44: 19-Aug-25 | W44: 1500 | X44: 32757 | Y44: 19-Aug-25 | AB44: 010 | AC44: LATE SUBMISSION | AD44: 100
A45: 44 | B45: NORTH | C45: UTTAR PRADESH | D45: 7134 | E45: M/S GOENKA AUTO PRIVATE LIMITED. | F45: VARANASI | G45: S | H45: 05-Mar-25 | I45: 1165 | J45: 00795725 | K45: MC1E4DAA1SP055832 | L45: D71068928 | M45: T-1 | N45: SCI26E000001 | O45: 13-Feb-2025 | P45: 09-Jul-25 | Q45: 1150 | R45: 0 | S45: 207 | T45: 1357 | U45: 621504 | V45: 19-Aug-25 | W45: 1150 | X45: 32757 | Y45: 19-Aug-25 | AB45: 010 | AC45: LATE SUBMISSION | AD45: 100
A46: 45 | B46: NORTH | C46: UTTAR PRADESH | D46: 7134 | E46: M/S GOENKA AUTO PRIVATE LIMITED. | F46: VARANASI | G46: S | H46: 13-Feb-25 | I46: 1165 | J46: 00326051 | K46: MC1D4DKA2SP105924 | L46: D72017397 | M46: TRAX | N46: SCI26E000001 | O46: 30-Nov-2024 | P46: 09-Jul-25 | Q46: 1150 | R46: 0 | S46: 207 | T46: 1357 | U46: 621504 | V46: 19-Aug-25 | W46: 1150 | X46: 32757 | Y46: 19-Aug-25 | AB46: 010 | AC46: LATE SUBMISSION | AD46: 100
A47: 46 | B47: NORTH | C47: UTTAR PRADESH | D47: 7134 | E47: M/S GOENKA AUTO PRIVATE LIMITED. | F47: VARANASI | G47: S | H47: 30-Mar-25 | I47: 1165 | J47: 00789038 | K47: MC1E4FCAXSP023177 | L47: D71076546 | M47: T26 | N47: SCI26E000002 | O47: 28-Mar-2025 | P47: 09-Jul-25 | Q47: 1150 | R47: 1150 | S47: 207 | T47: 1357 | U47: 621505 | V47: 19-Aug-25 | W47: 0 | X47: 32758 | Y47: 19-Aug-25
A48: 47 | B48: NORTH | C48: UTTAR PRADESH | D48: 7134 | E48: M/S GOENKA AUTO PRIVATE LIMITED. | F48: VARANASI | G48: S | H48: 22-Mar-25 | I48: 1160 | J48: 00801727 | K48: MC1E4DCA7SP056335 | L48: D71075083 | M48: T-1 | N48: SCI26E000002 | O48: 19-Mar-2025 | P48: 09-Jul-25 | Q48: 1150 | R48: 1150 | S48: 207 | T48: 1357 | U48: 621505 | V48: 19-Aug-25 | W48: 0 | X48: 32758 | Y48: 19-Aug-25
A49: 48 | B49: NORTH | C49: UTTAR PRADESH | D49: 7134 | E49: M/S GOENKA AUTO PRIVATE LIMITED. | F49: VARANASI | G49: S | H49: 18-Mar-25 | I49: 1165 | J49: 00789530 | K49: MC1E4FBA3SP022860 | L49: D71074009 | M49: T26 | N49: SCI26E000002 | O49: 12-Mar-2025 | P49: 09-Jul-25 | Q49: 1150 | R49: 1150 | S49: 207 | T49: 1357 | U49: 621505 | V49: 19-Aug-25 | W49: 0 | X49: 32758 | Y49: 19-Aug-25
A50: 49 | B50: NORTH | C50: UTTAR PRADESH | D50: 7134 | E50: M/S GOENKA AUTO PRIVATE LIMITED. | F50: VARANASI | G50: S | H50: 30-Mar-25 | I50: 1165 | J50: 00789023 | K50: MC1E4FCA2SP023089 | L50: D71076495 | M50: T26 | N50: SCI26E000002 | O50: 28-Mar-2025 | P50: 09-Jul-25 | Q50: 1150 | R50: 1150 | S50: 207 | T50: 1357 | U50: 621505 | V50: 19-Aug-25 | W50: 0 | X50: 32758 | Y50: 19-Aug-25
A51: 50 | B51: NORTH | C51: UTTAR PRADESH | D51: 7134 | E51: M/S GOENKA AUTO PRIVATE LIMITED. | F51: VARANASI | G51: S | H51: 30-Mar-25 | I51: 1165 | J51: 00798838 | K51: MC1E4DAA5SP055929 | L51: D71070921 | M51: T-1 | N51: SCI26E000002 | O51: 26-Feb-2025 | P51: 09-Jul-25 | Q51: 1150 | R51: 1150 | S51: 207 | T51: 1357 | U51: 621505 | V51: 19-Aug-25 | W51: 0 | X51: 32758 | Y51: 19-Aug-25
...

Sheet FSC report
A1: Sr. No. | B1: Zone | C1: State | D1: Dealer Code | E1: Dealer Name | F1: Location | G1: Sale Date | H1: Service Date | I1: Sale KMS/Hrs | J1: Service KMS/Hrs | K1: Service No. | L1: Scheme | M1: Vehicle Type | N1: Coupon No. | O1: Chassis No. | P1: Engine No. | Q1: Rejection Code | R1: Rejection Desc. | S1: GST Invoice No. | T1: Invoice Date | U1: Settlement Date | V1: Invoice Amount | W1: Credit Note No. | X1: Credit Note Date | Y1: Credit Amount | Z1: Net Amount | AA1: GST Amount | AB1: Debit Note No. | AC1: Debit Note Date | AD1: Debit Amount | AE1: FI Doc No Credit | AF1: FI Doc No Debit | AG1: Vehicle Sub Type | AH1: Division | AI1: Coupon Type
A2: 1 | B2: NORTH | C2: UTTAR PRADESH | D2: 7134 | E2: M/S GOENKA AUTO PRIVATE LIMITED. | F2: VARANASI | G2: 24-Jul-24 | H2: 14-Jul-25 | I2: 1165 | J2: 41684 | K2: 6 | L2: S | M2: T-1 | N2: 70774079 | O2: MC1E4DFA8RP053465 | P2: D71057531 | S2: 7134-20250923 | T2: 23-Sep-25 | U2: 23-Sep-25 | V2: 0 | W2: 0 | Y2: 0 | Z2: 0 | AA2: 0 | AB2: 0 | AD2: 0 | AG2: T1BS6 | AH2: CVD | AI2: P
A3: 2 | B3: NORTH | C3: UTTAR PRADESH | D3: 7134 | E3: M/S GOENKA AUTO PRIVATE LIMITED. | F3: VARANASI | G3: 25-Jan-24 | H3: 04-Feb-25 | I3: 1165 | J3: 68850 | K3: 7 | L3: S | M3: T-1 | N3: 761864 | O3: MC1E4EAA2RP011497 | P3: D71045143 | S3: SCI25C000036 | T3: 28-Feb-25 | U3: 15-Apr-25 | V3: 0 | W3: 587586 | X3: 03-Jun-25 | Y3: 0 | Z3: 0 | AA3: 0 | AB3: 111053 | AC3: 03-Jun-25 | AD3: 0 | AG3: T1BS6 | AH3: CVD | AI3: P
A4: 3 | B4: NORTH | C4: UTTAR PRADESH | D4: 7134 | E4: M/S GOENKA AUTO PRIVATE LIMITED. | F4: VARANASI | G4: 30-Oct-24 | H4: 28-Feb-25 | I4: 983 | J4: 8340 | K4: 2 | L4: S | M4: T26 | N4: 789173 | O4: MC1E4FHA0SP021351 | P4: D71060818 | S4: SCI25C000036 | T4: 28-Feb-25 | U4: 15-Apr-25 | V4: 0 | W4: 587586 | X4: 03-Jun-25 | Y4: 0 | Z4: 0 | AA4: 0 | AB4: 111053 | AC4: 03-Jun-25 | AD4: 0 | AG4: T26BS6 | AH4: CVD | AI4: P
A5: 4 | B5: NORTH | C5: UTTAR PRADESH | D5: 7134 | E5: M/S GOENKA AUTO PRIVATE LIMITED. | F5: VARANASI | G5: 26-Dec-24 | H5: 25-Feb-25 | I5: 1165 | J5: 4500 | K5: 1 | L5: S | M5: TRAX | N5: 324735 | O5: MC1D4DHA4SP105477 | P5: D72016904 | S5: SCI25C000036 | T5: 28-Feb-25 | U5: 15-Apr-25 | V5: 1250 | W5: 587586 | X5: 03-Jun-25 | Y5: 1250 | Z5: 1475 | AA5: 225 | AB5: 111053 | AC5: 03-Jun-25 | AD5: 0 | AG5: TRXBS6 | AH5: CVD | AI5: F
A6: 5 | B6: NORTH | C6: UTTAR PRADESH | D6: 7134 | E6: M/S GOENKA AUTO PRIVATE LIMITED. | F6: VARANASI | G6: 30-Jun-23 | H6: 02-Feb-25 | I6: 1165 | J6: 97230 | K6: 10 | L6: S | M6: TRAX | N6: 317176 | O6: MC1D4DFAXPP100326 | P6: D72010898 | S6: SCI25C000036 | T6: 28-Feb-25 | U6: 15-Apr-25 | V6: 0 | W6: 587586 | X6: 03-Jun-25 | Y6: 0 | Z6: 0 | AA6: 0 | AB6: 111053 | AC6: 03-Jun-25 | AD6: 0 | AG6: TRXBS6 | AH6: CVD | AI6: P
A7: 6 | B7: NORTH | C7: UTTAR PRADESH | D7: 7134 | E7: M/S GOENKA AUTO PRIVATE LIMITED. | F7: VARANASI | G7: 19-Aug-23 | H7: 27-Feb-25 | I7: 1160 | J7: 71600 | K7: 9 | L7: S | M7: T-1 | N7: 750964 | O7: MC1E4EHAXRP010300 | P7: D71037063 | S7: SCI25C000036 | T7: 28-Feb-25 | U7: 15-Apr-25 | V7: 0 | W7: 587586 | X7: 03-Jun-25 | Y7: 0 | Z7: 0 | AA7: 0 | AB7: 111053 | AC7: 03-Jun-25 | AD7: 0 | AG7: T1BS6 | AH7: CVD | AI7: P
A8: 7 | B8: NORTH | C8: UTTAR PRADESH | D8: 7134 | E8: M/S GOENKA AUTO PRIVATE LIMITED. | F8: VARANASI | G8: 20-Feb-24 | H8: 21-Feb-25 | I8: 1165 | J8: 60000 | K8: 6 | L8: S | M8: T26 | N8: 766692 | O8: MC1E4FAA9RP019134 | P8: D71046150 | S8: SCI25C000036 | T8: 28-Feb-25 | U8: 15-Apr-25 | V8: 0 | W8: 587586 | X8: 03-Jun-25 | Y8: 0 | Z8: 0 | AA8: 0 | AB8: 111053 | AC8: 03-Jun-25 | AD8: 0 | AG8: T26BS6 | AH8: CVD | AI8: P
A9: 8 | B9: NORTH | C9: UTTAR PRADESH | D9: 7134 | E9: M/S GOENKA AUTO PRIVATE LIMITED. | F9: VARANASI | G9: 31-Mar-23 | H9: 05-Feb-25 | I9: 1168 | J9: 28628 | K9: 12 | L9: S | M9: T-1 | N9: 744913 | O9: MC1E4DCA3PP044965 | P9: D71028276 | S9: SCI25C000036 | T9: 28-Feb-25 | U9: 15-Apr-25 | V9: 0 | W9: 587586 | X9: 03-Jun-25 | Y9: 0 | Z9: 0 | AA9: 0 | AB9: 111053 | AC9: 03-Jun-25 | AD9: 0 | AG9: T1BS6 | AH9: CVD | AI9: P
A10: 9 | B10: NORTH | C10: UTTAR PRADESH | D10: 7134 | E10: M/S GOENKA AUTO PRIVATE LIMITED. | F10: VARANASI | G10: 23-Aug-24 | H10: 17-Feb-25 | I10: 1165 | J10: 30000 | K10: 3 | L10: S | M10: T26 | N10: 776633 | O10: MC1E4FFA0RP020858 | P10: D71057668 | S10: SCI25C000036 | T10: 28-Feb-25 | U10: 15-Apr-25 | V10: 1250 | W10: 587586 | X10: 03-Jun-25 | Y10: 1250 | Z10: 1475 | AA10: 225 | AB10: 111053 | AC10: 03-Jun-25 | AD10: 0 | AG10: T26BS6 | AH10: CVD | AI10: F
A11: 10 | B11: NORTH | C11: UTTAR PRADESH | D11: 7134 | E11: M/S GOENKA AUTO PRIVATE LIMITED. | F11: VARANASI | G11: 30-Nov-24 | H11: 28-Feb-25 | I11: 1123 | J11: 9353 | K11: 1 | L11: S | M11: T-1 | N11: 785680 | O11: MC1E4EJA0SP014176 | P11: D71062910 | Q11: 002 | R11: SERV DATE EXCEEDS | S11: SCI25C000036 | T11: 28-Feb-25 | U11: 15-Apr-25 | V11: 1250 | W11: 587586 | X11: 03-Jun-25 | Y11: 1000 | Z11: 1475 | AA11: 225 | AB11: 111053 | AC11: 03-Jun-25 | AD11: 250 | AG11: T1BS6 | AH11: CVD | AI11: F
A12: 11 | B12: NORTH | C12: UTTAR PRADESH | D12: 7134 | E12: M/S GOENKA AUTO PRIVATE LIMITED. | F12: VARANASI | G12: 14-Oct-24 | H12: 04-Feb-25 | I12: 1165 | J12: 20000 | K12: 2 | L12: S | M12: T1N | N12: 5472 | O12: MC1M4AKA7SP002481 | P12: D71063459 | S12: SCI25C000036 | T12: 28-Feb-25 | U12: 15-Apr-25 | V12: 0 | W12: 587586 | X12: 03-Jun-25 | Y12: 0 | Z12: 0 | AA12: 0 | AB12: 111053 | AC12: 03-Jun-25 | AD12: 0 | AG12: URBN | AH12: CVD | AI12: P
A13: 12 | B13: NORTH | C13: UTTAR PRADESH | D13: 7134 | E13: M/S GOENKA AUTO PRIVATE LIMITED. | F13: VARANASI | G13: 29-Apr-24 | H13: 17-Feb-25 | I13: 1165 | J13: 68440 | K13: 7 | L13: S | M13: T-1 | N13: 773372 | O13: MC1E4EDA5RP012526 | P13: D71051928 | S13: SCI25C000036 | T13: 28-Feb-25 | U13: 15-Apr-25 | V13: 0 | W13: 587586 | X13: 03-Jun-25 | Y13: 0 | Z13: 0 | AA13: 0 | AB13: 111053 | AC13: 03-Jun-25 | AD13: 0 | AG13: T1BS6 | AH13: CVD | AI13: P
A14: 13 | B14: NORTH | C14: UTTAR PRADESH | D14: 7134 | E14: M/S GOENKA AUTO PRIVATE LIMITED. | F14: VARANASI | G14: 23-Jan-24 | H14: 03-Feb-25 | I14: 1165 | J14: 70000 | K14: 7 | L14: S | M14: T1N | N14: 2040 | O14: MC1M4AAA2RP000892 | P14: D71044975 | S14: SCI25C000036 | T14: 28-Feb-25 | U14: 15-Apr-25 | V14: 1650 | W14: 587586 | X14: 03-Jun-25 | Y14: 1650 | Z14: 1947 | AA14: 297 | AB14: 111053 | AC14: 03-Jun-25 | AD14: 0 | AG14: URBN | AH14: CVD | AI14: F
A15: 14 | B15: NORTH | C15: UTTAR PRADESH | D15: 7134 | E15: M/S GOENKA AUTO PRIVATE LIMITED. | F15: VARANASI | G15: 30-Sep-23 | H15: 02-Feb-25 | I15: 986 | J15: 101700 | K15: 10 | L15: S | M15: T-1 | N15: 752939 | O15: MC1E4DJA5RP048036 | P15: D71038347 | Q15: 001 | R15: SERV KMS / HRS EXCEEDS | S15: SCI25C000036 | T15: 28-Feb-25 | U15: 15-Apr-25 | V15: 0 | W15: 587586 | X15: 03-Jun-25 | Y15: 0 | Z15: 0 | AA15: 0 | AB15: 111053 | AC15: 03-Jun-25 | AD15: 0 | AG15: T1BS6 | AH15: CVD | AI15: P
A16: 15 | B16: NORTH | C16: UTTAR PRADESH | D16: 7134 | E16: M/S GOENKA AUTO PRIVATE LIMITED. | F16: VARANASI | G16: 21-Oct-24 | H16: 11-Feb-25 | I16: 1165 | J16: 19726 | K16: 2 | L16: S | M16: T-1 | N16: 787041 | O16: MC1E4EHA9SP013856 | P16: D71061114 | S16: SCI25C000036 | T16: 28-Feb-25 | U16: 15-Apr-25 | V16: 0 | W16: 587586 | X16: 03-Jun-25 | Y16: 0 | Z16: 0 | AA16: 0 | AB16: 111053 | AC16: 03-Jun-25 | AD16: 0 | AG16: T1BS6 | AH16: CVD | AI16: P
A17: 16 | B17: NORTH | C17: UTTAR PRADESH | D17: 7134 | E17: M/S GOENKA AUTO PRIVATE LIMITED. | F17: VARANASI | G17: 27-Jun-23 | H17: 28-Feb-25 | I17: 1165 | J17: 81000 | K17: 10 | L17: S | M17: T-1 | N17: 751781 | O17: MC1E4EFA5PP009796 | P17: D71032748 | S17: SCI25C000036 | T17: 28-Feb-25 | U17: 15-Apr-25 | V17: 0 | W17: 587586 | X17: 03-Jun-25 | Y17: 0 | Z17: 0 | AA17: 0 | AB17: 111053 | AC17: 03-Jun-25 | AD17: 0 | AG17: T1BS6 | AH17: CVD | AI17: P
A18: 17 | B18: NORTH | C18: UTTAR PRADESH | D18: 7134 | E18: M/S GOENKA AUTO PRIVATE LIMITED. | F18: VARANASI | G18: 31-Jul-23 | H18: 02-Feb-25 | I18: 1165 | J18: 53700 | K18: 10 | L18: S | M18: T-1 | N18: 751190 | O18: MC1E4DGA2RP046977 | P18: D71033670 | S18: SCI25C000036 | T18: 28-Feb-25 | U18: 15-Apr-25 | V18: 0 | W18: 587586 | X18: 03-Jun-25 | Y18: 0 | Z18: 0 | AA18: 0 | AB18: 111053 | AC18: 03-Jun-25 | AD18: 0 | AG18: T1BS6 | AH18: CVD | AI18: P
A19: 18 | B19: NORTH | C19: UTTAR PRADESH | D19: 7134 | E19: M/S GOENKA AUTO PRIVATE LIMITED. | F19: VARANASI | G19: 14-Jan-25 | H19: 26-Feb-25 | I19: 1165 | J19: 9540 | K19: 1 | L19: S | M19: T-1 | N19: 792074 | O19: MC1E4ELA2SP014645 | P19: D71065178 | S19: SCI25C000036 | T19: 28-Feb-25 | U19: 15-Apr-25 | V19: 1250 | W19: 587586 | X19: 03-Jun-25 | Y19: 1250 | Z19: 1475 | AA19: 225 | AB19: 111053 | AC19: 03-Jun-25 | AD19: 0 | AG19: T1BS6 | AH19: CVD | AI19: F
A20: 19 | B20: NORTH | C20: UTTAR PRADESH | D20: 7134 | E20: M/S GOENKA AUTO PRIVATE LIMITED. | F20: VARANASI | G20: 30-Sep-24 | H20: 13-Feb-25 | I20: 1165 | J20: 7840 | K20: 1 | L20: S | M20: T-1 | N20: 782166 | O20: MC1E4DGA9SP053950 | P20: D71059289 | S20: SCI25C000036 | T20: 28-Feb-25 | U20: 15-Apr-25 | V20: 1250 | W20: 587586 | X20: 03-Jun-25 | Y20: 1250 | Z20: 1475 | AA20: 225 | AB20: 111053 | AC20: 03-Jun-25 | AD20: 0 | AG20: T1BS6N | AH20: CVD | AI20: F
A21: 20 | B21: NORTH | C21: UTTAR PRADESH | D21: 7134 | E21: M/S GOENKA AUTO PRIVATE LIMITED. | F21: VARANASI | G21: 18-Jan-25 | H21: 12-Feb-25 | I21: 1165 | J21: 9678 | K21: 1 | L21: S | M21: T-1 | N21: 790037 | O21: MC1E4EKA7SP014402 | P21: D71064055 | S21: SCI25C000036 | T21: 28-Feb-25 | U21: 15-Apr-25 | V21: 1250 | W21: 587586 | X21: 03-Jun-25 | Y21: 1250 | Z21: 1475 | AA21: 225 | AB21: 111053 | AC21: 03-Jun-25 | AD21: 0 | AG21: T1BS6 | AH21: CVD | AI21: F
A22: 21 | B22: NORTH | C22: UTTAR PRADESH | D22: 7134 | E22: M/S GOENKA AUTO PRIVATE LIMITED. | F22: VARANASI | G22: 13-Jul-24 | H22: 27-Feb-25 | I22: 1165 | J22: 60000 | K22: 6 | L22: S | M22: T-1 | N22: 775456 | O22: MC1E4EEA5RP013061 | P22: D71055469 | S22: SCI25C000036 | T22: 28-Feb-25 | U22: 15-Apr-25 | V22: 0 | W22: 587586 | X22: 03-Jun-25 | Y22: 0 | Z22: 0 | AA22: 0 | AB22: 111053 | AC22: 03-Jun-25 | AD22: 0 | AG22: T1BS6 | AH22: CVD | AI22: P
A23: 22 | B23: NORTH | C23: UTTAR PRADESH | D23: 7134 | E23: M/S GOENKA AUTO PRIVATE LIMITED. | F23: VARANASI | G23: 23-Feb-23 | H23: 18-Feb-25 | I23: 1165 | J23: 132403 | K23: 14 | L23: S | M23: T1N | N23: 1189 | O23: MC1M4ABAXPP000151 | P23: D71026417 | S23: SCI25C000036 | T23: 28-Feb-25 | U23: 15-Apr-25 | V23: 0 | W23: 587586 | X23: 03-Jun-25 | Y23: 0 | Z23: 0 | AA23: 0 | AB23: 111053 | AC23: 03-Jun-25 | AD23: 0 | AG23: URBN | AH23: CVD | AI23: P
A24: 23 | B24: NORTH | C24: UTTAR PRADESH | D24: 7134 | E24: M/S GOENKA AUTO PRIVATE LIMITED. | F24: VARANASI | G24: 22-Mar-23 | H24: 25-Feb-25 | I24: 1165 | J24: 74200 | K24: 12 | L24: S | M24: T-1 | N24: 743522 | O24: MC1E4EBA3PP009155 | P24: D71026032 | S24: SCI25C000036 | T24: 28-Feb-25 | U24: 15-Apr-25 | V24: 0 | W24: 587586 | X24: 03-Jun-25 | Y24: 0 | Z24: 0 | AA24: 0 | AB24: 111053 | AC24: 03-Jun-25 | AD24: 0 | AG24: T1BS6 | AH24: CVD | AI24: P
A25: 24 | B25: NORTH | C25: UTTAR PRADESH | D25: 7134 | E25: M/S GOENKA AUTO PRIVATE LIMITED. | F25: VARANASI | G25: 28-Dec-24 | H25: 11-Feb-25 | I25: 1108 | J25: 10000 | K25: 1 | L25: S | M25: T1N | N25: 5897 | O25: MC1M4ALA7SP002849 | P25: D71066165 | S25: SCI25C000036 | T25: 28-Feb-25 | U25: 15-Apr-25 | V25: 1650 | W25: 587586 | X25: 03-Jun-25 | Y25: 1650 | Z25: 1947 | AA25: 297 | AB25: 111053 | AC25: 03-Jun-25 | AD25: 0 | AG25: URBN | AH25: CVD | AI25: F
A26: 25 | B26: NORTH | C26: UTTAR PRADESH | D26: 7134 | E26: M/S GOENKA AUTO PRIVATE LIMITED. | F26: VARANASI | G26: 09-Aug-24 | H26: 10-Feb-25 | I26: 1165 | J26: 39210 | K26: 4 | L26: S | M26: T-1 | N26: 774600 | O26: MC1E4EFA8RP013148 | P26: D71056274 | S26: SCI25C000036 | T26: 28-Feb-25 | U26: 15-Apr-25 | V26: 0 | W26: 587586 | X26: 03-Jun-25 | Y26: 0 | Z26: 0 | AA26: 0 | AB26: 111053 | AC26: 03-Jun-25 | AD26: 0 | AG26: T1BS6 | AH26: CVD | AI26: P
A27: 26 | B27: NORTH | C27: UTTAR PRADESH | D27: 7134 | E27: M/S GOENKA AUTO PRIVATE LIMITED. | F27: VARANASI | G27: 28-Mar-24 | H27: 24-Feb-25 | I27: 1165 | J27: 49910 | K27: 5 | L27: S | M27: T1N | N27: 3405 | O27: MC1M4ACA6RP001203 | P27: D71050375 | S27: SCI25C000036 | T27: 28-Feb-25 | U27: 15-Apr-25 | V27: 1650 | W27: 587586 | X27: 03-Jun-25 | Y27: 1650 | Z27: 1947 | AA27: 297 | AB27: 111053 | AC27: 03-Jun-25 | AD27: 0 | AG27: URBN | AH27: CVD | AI27: F
A28: 27 | B28: NORTH | C28: UTTAR PRADESH | D28: 7134 | E28: M/S GOENKA AUTO PRIVATE LIMITED. | F28: VARANASI | G28: 09-Mar-24 | H28: 07-Feb-25 | I28: 1165 | J28: 50000 | K28: 5 | L28: S | M28: T1N | N28: 3152 | O28: MC1M4ABA5RP001114 | P28: D71048194 | S28: SCI25C000036 | T28: 28-Feb-25 | U28: 15-Apr-25 | V28: 1650 | W28: 587586 | X28: 03-Jun-25 | Y28: 1650 | Z28: 1947 | AA28: 297 | AB28: 111053 | AC28: 03-Jun-25 | AD28: 0 | AG28: URBN | AH28: CVD | AI28: F
A29: 28 | B29: NORTH | C29: UTTAR PRADESH | D29: 7134 | E29: M/S GOENKA AUTO PRIVATE LIMITED. | F29: VARANASI | G29: 30-Oct-24 | H29: 03-Feb-25 | I29: 1165 | J29: 10000 | K29: 1 | L29: S | M29: T-1 | N29: 790580 | O29: MC1E4EKA2SP014274 | P29: D71063383 | Q29: 002 | R29: SERV DATE EXCEEDS | S29: SCI25C000036 | T29: 28-Feb-25 | U29: 15-Apr-25 | V29: 1250 | W29: 587586 | X29: 03-Jun-25 | Y29: 1000 | Z29: 1475 | AA29: 225 | AB29: 111053 | AC29: 03-Jun-25 | AD29: 250 | AG29: T1BS6 | AH29: CVD | AI29: F
A30: 29 | B30: NORTH | C30: UTTAR PRADESH | D30: 7134 | E30: M/S GOENKA AUTO PRIVATE LIMITED. | F30: VARANASI | G30: 30-Oct-24 | H30: 24-Feb-25 | I30: 1165 | J30: 19200 | K30: 2 | L30: S | M30: TRAX | N30: 324816 | O30: MC1D4DHAXSP105385 | P30: D72016803 | S30: SCI25C000036 | T30: 28-Feb-25 | U30: 15-Apr-25 | V30: 0 | W30: 587586 | X30: 03-Jun-25 | Y30: 0 | Z30: 0 | AA30: 0 | AB30: 111053 | AC30: 03-Jun-25 | AD30: 0 | AG30: TRXBS6 | AH30: CVD | AI30: P
A31: 30 | B31: NORTH | C31: UTTAR PRADESH | D31: 7134 | E31: M/S GOENKA AUTO PRIVATE LIMITED. | F31: VARANASI | G31: 11-Sep-24 | H31: 25-Feb-25 | I31: 1165 | J31: 13000 | K31: 3 | L31: S | M31: T-1 | N31: 786359 | O31: MC1E4EHA9SP013713 | P31: D71060226 | S31: SCI25C000036 | T31: 28-Feb-25 | U31: 15-Apr-25 | V31: 1250 | W31: 587586 | X31: 03-Jun-25 | Y31: 1250 | Z31: 1475 | AA31: 225 | AB31: 111053 | AC31: 03-Jun-25 | AD31: 0 | AG31: T1BS6 | AH31: CVD | AI31: F
A32: 31 | B32: NORTH | C32: UTTAR PRADESH | D32: 7134 | E32: M/S GOENKA AUTO PRIVATE LIMITED. | F32: VARANASI | G32: 29-Jun-24 | H32: 25-Feb-25 | I32: 1165 | J32: 50000 | K32: 5 | L32: S | M32: T-1 | N32: 775226 | O32: MC1E4EFA5RP013091 | P32: D71055952 | S32: SCI25C000036 | T32: 28-Feb-25 | U32: 15-Apr-25 | V32: 1250 | W32: 587586 | X32: 03-Jun-25 | Y32: 1250 | Z32: 1475 | AA32: 225 | AB32: 111053 | AC32: 03-Jun-25 | AD32: 0 | AG32: T1BS6 | AH32: CVD | AI32: F
A33: 32 | B33: NORTH | C33: UTTAR PRADESH | D33: 7134 | E33: M/S GOENKA AUTO PRIVATE LIMITED. | F33: VARANASI | G33: 28-May-24 | H33: 07-Feb-25 | I33: 1165 | J33: 50000 | K33: 5 | L33: S | M33: T26 | N33: 776290 | O33: MC1E4FEA9RP020391 | P33: D71054667 | S33: SCI25C000036 | T33: 28-Feb-25 | U33: 15-Apr-25 | V33: 1250 | W33: 587586 | X33: 03-Jun-25 | Y33: 1250 | Z33: 1475 | AA33: 225 | AB33: 111053 | AC33: 03-Jun-25 | AD33: 0 | AG33: T26BS6 | AH33: CVD | AI33: F
A34: 33 | B34: NORTH | C34: UTTAR PRADESH | D34: 7134 | E34: M/S GOENKA AUTO PRIVATE LIMITED. | F34: VARANASI | G34: 27-Jan-23 | H34: 04-Feb-25 | I34: 1165 | J34: 43446 | K34: 12 | L34: S | M34: T-1 | N34: 739521 | O34: MC1E4DMA6PP043808 | P34: D71023849 | S34: SCI25C000036 | T34: 28-Feb-25 | U34: 15-Apr-25 | V34: 0 | W34: 587586 | X34: 03-Jun-25 | Y34: 0 | Z34: 0 | AA34: 0 | AB34: 111053 | AC34: 03-Jun-25 | AD34: 0 | AG34: T1BS6 | AH34: CVD | AI34: P
A35: 34 | B35: NORTH | C35: UTTAR PRADESH | D35: 7134 | E35: M/S GOENKA AUTO PRIVATE LIMITED. | F35: VARANASI | G35: 18-Jun-24 | H35: 28-Feb-25 | I35: 1165 | J35: 40000 | K35: 4 | L35: S | M35: T26 | N35: 776484 | O35: MC1E4FDA3RP020209 | P35: D71053461 | S35: SCI25C000036 | T35: 28-Feb-25 | U35: 15-Apr-25 | V35: 0 | W35: 587586 | X35: 03-Jun-25 | Y35: 0 | Z35: 0 | AA35: 0 | AB35: 111053 | AC35: 03-Jun-25 | AD35: 0 | AG35: T26BS6 | AH35: CVD | AI35: P
A36: 35 | B36: NORTH | C36: UTTAR PRADESH | D36: 7134 | E36: M/S GOENKA AUTO PRIVATE LIMITED. | F36: VARANASI | G36: 09-Mar-24 | H36: 25-Feb-25 | I36: 1165 | J36: 35149 | K36: 6 | L36: S | M36: T-1 | N36: 764716 | O36: MC1E4EAA5RP011669 | P36: D71046362 | S36: SCI25C000036 | T36: 28-Feb-25 | U36: 15-Apr-25 | V36: 0 | W36: 587586 | X36: 03-Jun-25 | Y36: 0 | Z36: 0 | AA36: 0 | AB36: 111053 | AC36: 03-Jun-25 | AD36: 0 | AG36: T1BS6 | AH36: CVD | AI36: P
A37: 36 | B37: NORTH | C37: UTTAR PRADESH | D37: 7134 | E37: M/S GOENKA AUTO PRIVATE LIMITED. | F37: VARANASI | G37: 31-Dec-24 | H37: 26-Feb-25 | I37: 1165 | J37: 10000 | K37: 1 | L37: S | M37: T1N | N37: 6182 | O37: MC1M4AMA9SP003001 | P37: D71066870 | S37: SCI25C000036 | T37: 28-Feb-25 | U37: 15-Apr-25 | V37: 1650 | W37: 587586 | X37: 03-Jun-25 | Y37: 1650 | Z37: 1947 | AA37: 297 | AB37: 111053 | AC37: 03-Jun-25 | AD37: 0 | AG37: URBN | AH37: CVD | AI37: F
A38: 37 | B38: NORTH | C38: UTTAR PRADESH | D38: 7134 | E38: M/S GOENKA AUTO PRIVATE LIMITED. | F38: VARANASI | G38: 20-Aug-24 | H38: 12-Feb-25 | I38: 1165 | J38: 37919 | K38: 4 | L38: S | M38: TRAX | N38: 323055 | O38: MC1D4DFAXRP104783 | P38: D72015804 | S38: SCI25C000036 | T38: 28-Feb-25 | U38: 15-Apr-25 | V38: 0 | W38: 587586 | X38: 03-Jun-25 | Y38: 0 | Z38: 0 | AA38: 0 | AB38: 111053 | AC38: 03-Jun-25 | AD38: 0 | AG38: TRXBS6 | AH38: CVD | AI38: P
A39: 38 | B39: NORTH | C39: UTTAR PRADESH | D39: 7134 | E39: M/S GOENKA AUTO PRIVATE LIMITED. | F39: VARANASI | G39: 31-Oct-24 | H39: 02-Feb-25 | I39: 936 | J39: 29900 | K39: 2 | L39: S | M39: T-1 | N39: 782758 | O39: MC1E4CKA4SP081267 | P39: D71063533 | S39: SCI25C000036 | T39: 28-Feb-25 | U39: 15-Apr-25 | V39: 1250 | W39: 587586 | X39: 03-Jun-25 | Y39: 1250 | Z39: 1475 | AA39: 225 | AB39: 111053 | AC39: 03-Jun-25 | AD39: 0 | AG39: T1BS6 | AH39: CVD | AI39: F
A40: 39 | B40: NORTH | C40: UTTAR PRADESH | D40: 7134 | E40: M/S GOENKA AUTO PRIVATE LIMITED. | F40: VARANASI | G40: 26-Sep-23 | H40: 26-Feb-25 | I40: 1165 | J40: 63374 | K40: 9 | L40: S | M40: T-1 | N40: 753565 | O40: MC1E4EJA6RP010529 | P40: D71039065 | S40: SCI25C000036 | T40: 28-Feb-25 | U40: 15-Apr-25 | V40: 0 | W40: 587586 | X40: 03-Jun-25 | Y40: 0 | Z40: 0 | AA40: 0 | AB40: 111053 | AC40: 03-Jun-25 | AD40: 0 | AG40: T1BS6 | AH40: CVD | AI40: P
...

Sheet Warranty report
A1: EDP No. | B1: Invoice Number | C1: Invoice Date | D1: Printed No | E1: Mfg Claim Id | F1: Claim Id | G1: Received Date | H1: Accept Date | I1: Chassis No. | J1: Engine No. | K1: Vehicle Type | L1: Sale Date | M1: Sale Kms/Hrs | N1: Fail Date | O1: Fail Kms | P1: GST Inv Rej Cd | Q1: GST_Inv_Rej_Desc | R1: Item Serial | S1: Item Code | T1: Item Description | U1: Qty | V1: Credit Rs. | W1: Remark | X1: Rej Code | Y1: Rejection Description | Z1: CR Note Details | AA1: CR Note Date | AB1: GST Invc Amt(A) | AC1: Dealer Debit Amt (B) | AD1: Debit Note No for Rej Claim | AE1: Debit Note Dt | AF1: Actual Credit Amt To dealer (A-B) | AG1: SAP Cr note no | AH1: SAP Db note no | AI1: Comment on Claim
A2: 1007718 | B2: WCI25C000101 | C2: 27-03-2025 | D2: 7134260110957 | E2: W25C00007502 | F2: WAR25C000105 | G2: 01-04-2025 | H2: 07-04-2025 | I2: MC1D4DFA0RP104744 | J2: D72015770 | K2: TRAX | L2: 03-07-2024 | M2: 1165 | N2: 04-03-2025 | O2: 58623 | R2: 1 | S2: B008545002003 | T2: RADIATOR ASSLY(RFR B | U2: 1 | V2: 5322.44 | W2: Accepted | Y2: - | Z2: 1749467 | AA2: 05-06-2025 | AB2: 6812.72 | AC2: 0 | AF2: 6812.72
A3: 1007718 | B3: WCI25C000101 | C3: 27-03-2025 | D3: 7134260110957 | E3: W25C00007502 | F3: WAR25C000105 | G3: 01-04-2025 | H3: 07-04-2025 | I3: MC1D4DFA0RP104744 | J3: D72015770 | K3: TRAX | L3: 03-07-2024 | M3: 1165 | N3: 04-03-2025 | O3: 58623 | R3: 2 | S3: ENCOL-6 | T3: Labour Charges | U3: 1 | V3: 247.5 | W3: Accepted | Y3: - | Z3: 1749467 | AA3: 05-06-2025 | AB3: 292.05 | AC3: 0 | AF3: 292.05
A4: 1007734 | B4: WCI25C000100 | C4: 27-03-2025 | D4: 7134260110956 | E4: W25C00007501 | F4: WAR25C000104 | G4: 01-04-2025 | H4: 07-04-2025 | I4: MC1D4DHA2SP105199 | J4: D72016528 | K4: TRAX | L4: 24-08-2024 | M4: 1165 | N4: 04-03-2025 | O4: 42369 | R4: 1 | S4: B008545002003 | T4: RADIATOR ASSLY(RFR B | U4: 1 | V4: 5322.44 | W4: Accepted | Y4: - | Z4: 1749466 | AA4: 05-06-2025 | AB4: 6812.72 | AC4: 0 | AF4: 6812.72
A5: 1007734 | B5: WCI25C000100 | C5: 27-03-2025 | D5: 7134260110956 | E5: W25C00007501 | F5: WAR25C000104 | G5: 01-04-2025 | H5: 07-04-2025 | I5: MC1D4DHA2SP105199 | J5: D72016528 | K5: TRAX | L5: 24-08-2024 | M5: 1165 | N5: 04-03-2025 | O5: 42369 | R5: 2 | S5: ENCOL-6 | T5: Labour Charges | U5: 1 | V5: 247.5 | W5: Accepted | Y5: - | Z5: 1749466 | AA5: 05-06-2025 | AB5: 292.05 | AC5: 0 | AF5: 292.05
A6: 1008722 | B6: WCI26C000008 | C6: 30-04-2025 | D6: 7134260112212 | E6: W26C00000808 | F6: WAR26C000008 | G6: 08-05-2025 | H6: 29-05-2025 | I6: MC1E4EHA1SP013740 | J6: D71060115 | K6: T-1 | L6: 21-09-2024 | M6: 1165 | N6: 04-03-2025 | O6: 32256 | R6: 1 | S6: B008624200017 | T6: PARKING BRAKE ASSY. | U6: 1 | V6: 1436.28 | W6: Accepted | Y6: - | Z6: 1750232 | AA6: 10-07-2025 | AB6: 1838.44 | AC6: 0 | AF6: 1838.44
A7: 1008722 | B7: WCI26C000008 | C7: 30-04-2025 | D7: 7134260112212 | E7: W26C00000808 | F7: WAR26C000008 | G7: 08-05-2025 | H7: 29-05-2025 | I7: MC1E4EHA1SP013740 | J7: D71060115 | K7: T-1 | L7: 21-09-2024 | M7: 1165 | N7: 04-03-2025 | O7: 32256 | R7: 2 | S7: BR1201 | T7: Labour Charges | U7: 1 | V7: 75 | W7: Accepted | Y7: - | Z7: 1750232 | AA7: 10-07-2025 | AB7: 88.5 | AC7: 0 | AF7: 88.5
A8: 1008965 | B8: WCI26C000009 | C8: 30-04-2025 | D8: 7134260112223 | E8: W26C00000816 | F8: WAR26C000010 | G8: 13-05-2025 | H8: 29-05-2025 | I8: MC1E4DBA3RP050768 | J8: D71047053 | K8: T-1 | L8: 29-03-2024 | M8: 1165 | N8: 04-03-2025 | O8: 18290 | R8: 1 | S8: T006865420618 | T8: TEMPERATURE SENSOR(E | U8: 1 | V8: 9241.26 | W8: Accepted | Y8: - | Z8: 1750233 | AA8: 10-07-2025 | AB8: 11828.81 | AC8: 0 | AF8: 11828.81 | AI8: Adblue light on error code P242A-13,P2BA8-00
A9: 1008965 | B9: WCI26C000009 | C9: 30-04-2025 | D9: 7134260112223 | E9: W26C00000816 | F9: WAR26C000010 | G9: 13-05-2025 | H9: 29-05-2025 | I9: MC1E4DBA3RP050768 | J9: D71047053 | K9: T-1 | L9: 29-03-2024 | M9: 1165 | N9: 04-03-2025 | O9: 18290 | R9: 2 | S9: EX-4 | T9: Labour Charges | U9: 1 | V9: 105 | W9: Accepted | Y9: - | Z9: 1750233 | AA9: 10-07-2025 | AB9: 123.9 | AC9: 0 | AF9: 123.9 | AI9: Adblue light on error code P242A-13,P2BA8-00
A10: 1009012 | B10: WCI26C000001 | C10: 30-04-2025 | D10: 7134260112186 | E10: W26C00000782 | F10: WAR26C000001 | G10: 13-05-2025 | H10: 29-05-2025 | I10: MC1E4FHA8SP021288 | J10: D71060855 | K10: T26 | L10: 10-09-2024 | M10: 1165 | N10: 12-04-2025 | O10: 31578 | R10: 1 | S10: T006868200542 | T10: WIPER MOTOR ASSY - R | U10: 1 | V10: 1098.95 | W10: Rejected | X10: 04 | Y10: VEHICLE OUT OF WARRANTY KILOMETER WISE / TIME WISE | Z10: 1750225 | AA10: 10-07-2025 | AB10: 1296.76 | AC10: 1296.76 | AD10: 1517573 | AE10: 10-07-2025 | AF10: 0
A11: 1009012 | B11: WCI26C000001 | C11: 30-04-2025 | D11: 7134260112186 | E11: W26C00000782 | F11: WAR26C000001 | G11: 13-05-2025 | H11: 29-05-2025 | I11: MC1E4FHA8SP021288 | J11: D71060855 | K11: T26 | L11: 10-09-2024 | M11: 1165 | N11: 12-04-2025 | O11: 31578 | R11: 2 | S11: BD0801 | T11: Labour Charges | U11: 1 | V11: 142.5 | W11: Rejected | X11: 04 | Y11: VEHICLE OUT OF WARRANTY KILOMETER WISE / TIME WISE | Z11: 1750225 | AA11: 10-07-2025 | AB11: 168.15 | AC11: 168.15 | AD11: 1517573 | AE11: 10-07-2025 | AF11: 0
A12: 1009618 | B12: WCI26E000004 | C12: 31-05-2025 | D12: 7134260112969 | E12: W26C00001505 | F12: WAR26C000014 | G12: 04-06-2025 | H12: 23-07-2025 | I12: MC1E4EEA5RP013061 | J12: D71055469 | K12: T-1 | L12: 13-07-2024 | M12: 1160 | N12: 22-04-2025 | O12: 81254 | R12: 1 | S12: B008092000001 | T12: WATER PUMP ASSY (TD | U12: 1 | V12: 2541.6 | W12: Accepted | Y12: - | Z12: 1752230 | AA12: 25-09-2025 | AB12: 3091.9 | AC12: 0 | AF12: 3091.9
