Workbook
Name Part_Code: 'Spare Part IN'!$D:$D

Sheet HOW TO USE
A2: 1) Fill all Job card details in yellow tab " JOB CARD"
A4: 2) Fill all Purchase part details in green tab " Spare Part IN"
A6: 3) Inventory check - this gives you current spare parts stock
A7: a) go to red tab " Inventory Check".
A8: b) Click on "DATA" on menu bar
A9: c) Click on "Refresh ALL"
A10: d) Print the table under the Spare in Heading - Current parts qty with Rack number given
A12: 4) Daily Reporting
A13: a) Go to the blur coloured "Daily Report" Tab
A14: b) Click on "DATA" on menu bar
A15: c) Click on "Refresh ALL"
A16: d) Copy all data and send on whtsapp group

Sheet Job Card
A1: Job Card Opening Date | B1: Job Card Closing Date | C1: Job Card No | D1: Customer Name | E1: Customer Phone Number | F1: Vehicle number | G1: Vehicle Model | H1: Customer category | I1: Type Of Service | J1: Part Code Issued | K1: Part Description | L1: Part Qty | M1: Part MRP | N1: Part Value | O1: Labour Charges | P1: Electrical Labour | Q1: Outside Labour | R1: Laptop Charges | S1: Deputation | T1: Other charges | U1: Total Labour | V1: GST on Lobour | W1: Invoice No | X1: Total Invoice Value | Y1: Description of Outside Job | Z1: Amount paid for Outside Job | AA1: Day | AB1: Month | AC1: Year | AQ1: Types of service | AS1: Types of service | AT1: Vehicle Category
A2: 21/12/2025 | B2: 46012 | C2: 2051 | D2: THAKUR G PUBLIC SCHOOL NANDGANJ | E2: 7317881004 | F2: UP61BT3894 | G2: T2 | H2: School | I2: Paid | J2: Gulf Force BS VI (6.5L) | K2: =_xlfn.XLOOKUP(Job_Cards[[#This Row],[Part Code Issued]],'Inventory Check'!$A$3:$A$3000,'Inventory Check'!$B$3:$B$3000,"WRONG Code",0) -> Gulf Force BS VI (6.5L) | L2: 1 | M2: 2080 | N2: =M2*L2 -> 2080 | O2: 950 | U2: =SUM(O2:T2) -> 950 | V2: =U2*0.18 -> 171 | X2: =Job_Cards[[#This Row],[GST on Lobour]]+Job_Cards[[#This Row],[Total Labour]]+Job_Cards[[#This Row],[Part Value]] -> 3201 | AA2: =DAY(B2) -> 21 | AB2: =MONTH(B2) -> 12 | AC2: =YEAR(B2) -> 2025 | AQ2: Free Service | AS2: Free Service | AT2: T1
B3: 46012 | I3: =IF(Job_Cards[[#This Row],[Customer Name]]="",I2,"") -> Paid | J3: B008081803210 | K3: =_xlfn.XLOOKUP(Job_Cards[[#This Row],[Part Code Issued]],'Inventory Check'!$A$3:$A$3000,'Inventory Check'!$B$3:$B$3000,"WRONG Code",0) -> Oil Filter | L3: 1 | M3: 359 | N3: =M3*L3 -> 359 | U3: =SUM(O3:T3) -> 0 | V3: =U3*0.18 -> 0 | X3: =Job_Cards[[#This Row],[GST on Lobour]]+Job_Cards[[#This Row],[Total Labour]]+Job_Cards[[#This Row],[Part Value]] -> 359 | AA3: =DAY(B3) -> 21 | AB3: =MONTH(B3) -> 12 | AC3: =YEAR(B3) -> 2025 | AQ3: Paid | AS3: Paid | AT3: T2
B4: 46012 | I4: =IF(Job_Cards[[#This Row],[Customer Name]]="",I3,"") -> Paid | J4: B008080900252 | K4: =_xlfn.XLOOKUP(Job_Cards[[#This Row],[Part Code Issued]],'Inventory Check'!$A$3:$A$3000,'Inventory Check'!$B$3:$B$3000,"WRONG Code",0) -> FUEL FILTER | L4: 1 | M4: 1575 | N4: =M4*L4 -> 1575 | U4: =SUM(O4:T4) -> 0 | V4: =U4*0.18 -> 0 | X4: =Job_Cards[[#This Row],[GST on Lobour]]+Job_Cards[[#This Row],[Total Labour]]+Job_Cards[[#This Row],[Part Value]] -> 1575 | AA4: =DAY(B4) -> 21 | AB4: =MONTH(B4) -> 12 | AC4: =YEAR(B4) -> 2025 | AQ4: Breakdown | AS4: Breakdown | AT4: T3
B5: 46012 | I5: =IF(Job_Cards[[#This Row],[Customer Name]]="",I4,"") -> Paid | J5: Gulf Force AdBlue (20 L) | K5: =_xlfn.XLOOKUP(Job_Cards[[#This Row],[Part Code Issued]],'Inventory Check'!$A$3:$A$3000,'Inventory Check'!$B$3:$B$3000,"WRONG Code",0) -> Gulf Force AdBlue (20 L) | L5: 1 | M5: 1480 | N5: =M5*L5 -> 1480 | U5: =SUM(O5:T5) -> 0 | V5: =U5*0.18 -> 0 | X5: =Job_Cards[[#This Row],[GST on Lobour]]+Job_Cards[[#This Row],[Total Labour]]+Job_Cards[[#This Row],[Part Value]] -> 1480 | AA5: =DAY(B5) -> 21 | AB5: =MONTH(B5) -> 12 | AC5: =YEAR(B5) -> 2025 | AQ5: PDI | AS5: PDI | AT5: Trax
B6: 46012 | I6: =IF(Job_Cards[[#This Row],[Customer Name]]="",I5,"") -> Paid | J6: T006860940280 | K6: =_xlfn.XLOOKUP(Job_Cards[[#This Row],[Part Code Issued]],'Inventory Check'!$A$3:$A$3000,'Inventory Check'!$B$3:$B$3000,"WRONG Code",0) -> AIR FILTER | L6: 1 | M6: 1388 | N6: =M6*L6 -> 1388 | U6: =SUM(O6:T6) -> 0 | V6: =U6*0.18 -> 0 | X6: =Job_Cards[[#This Row],[GST on Lobour]]+Job_Cards[[#This Row],[Total Labour]]+Job_Cards[[#This Row],[Part Value]] -> 1388 | AA6: =DAY(B6) -> 21 | AB6: =MONTH(B6) -> 12 | AC6: =YEAR(B6) -> 2025 | AQ6: Warranty | AS6: Warranty | AT6: Urbania
A7: 21/12/2025 | B7: 46017 | C7: 2052 | D7: SUNBEAM SCHOOL DILDAR NAGAR | E7: 8545824480 | F7: UP61BT3610 | G7: T1 | H7: School | I7: Paid | J7: Gulf Force BS VI (6.5L) | K7: =_xlfn.XLOOKUP(Job_Cards[[#This Row],[Part Code Issued]],'Inventory Check'!$A$3:$A$3000,'Inventory Check'!$B$3:$B$3000,"WRONG Code",0) -> Gulf Force BS VI (6.5L) | L7: 1 | M7: 2080 | N7: =M7*L7 -> 2080 | O7: 850 | U7: =SUM(O7:T7) -> 850 | V7: =U7*0.18 -> 153 | X7: =Job_Cards[[#This Row],[GST on Lobour]]+Job_Cards[[#This Row],[Total Labour]]+Job_Cards[[#This Row],[Part Value]] -> 3083 | AA7: =DAY(B7) -> 26 | AB7: =MONTH(B7) -> 12 | AC7: =YEAR(B7) -> 2025 | AQ7: Counter Sale | AS7: Counter Sale
B8: 46017 | I8: =IF(Job_Cards[[#This Row],[Customer Name]]="",I7,"") -> Paid | J8: B008081803210 | K8: =_xlfn.XLOOKUP(Job_Cards[[#This Row],[Part Code Issued]],'Inventory Check'!$A$3:$A$3000,'Inventory Check'!$B$3:$B$3000,"WRONG Code",0) -> Oil Filter | L8: 1 | M8: 359 | N8: =M8*L8 -> 359 | U8: =SUM(O8:T8) -> 0 | V8: =U8*0.18 -> 0 | X8: =Job_Cards[[#This Row],[GST on Lobour]]+Job_Cards[[#This Row],[Total Labour]]+Job_Cards[[#This Row],[Part Value]] -> 359 | AA8: =DAY(B8) -> 26 | AB8: =MONTH(B8) -> 12 | AC8: =YEAR(B8) -> 2025
A9: 21/12/2025 | B9: 46017 | C9: 2053 | D9: SUNBEAM SCHOOL DILDAR NAGER | E9: 8545824480 | F9: UP61AT9745 | G9: T1 | H9: School | I9: Paid | J9: Gulf Force BS VI (6.5L) | K9: =_xlfn.XLOOKUP(Job_Cards[[#This Row],[Part Code Issued]],'Inventory Check'!$A$3:$A$3000,'Inventory Check'!$B$3:$B$3000,"WRONG Code",0) -> Gulf Force BS VI (6.5L) | L9: 1 | M9: 2080 | N9: =M9*L9 -> 2080 | O9: 850 | U9: =SUM(O9:T9) -> 850 | V9: =U9*0.18 -> 153 | X9: =Job_Cards[[#This Row],[GST on Lobour]]+Job_Cards[[#This Row],[Total Labour]]+Job_Cards[[#This Row],[Part Value]] -> 3083 | AA9: =DAY(B9) -> 26 | AB9: =MONTH(B9) -> 12 | AC9: =YEAR(B9) -> 2025
B10: 46017 | I10: =IF(Job_Cards[[#This Row],[Customer Name]]="",I9,"") -> Paid | J10: B008081803210 | K10: =_xlfn.XLOOKUP(Job_Cards[[#This Row],[Part Code Issued]],'Inventory Check'!$A$3:$A$3000,'Inventory Check'!$B$3:$B$3000,"WRONG Code",0) -> Oil Filter | L10: 1 | M10: 359 | N10: =M10*L10 -> 359 | U10: =SUM(O10:T10) -> 0 | V10: =U10*0.18 -> 0 | X10: =Job_Cards[[#This Row],[GST on Lobour]]+Job_Cards[[#This Row],[Total Labour]]+Job_Cards[[#This Row],[Part Value]] -> 359 | AA10: =DAY(B10) -> 26 | AB10: =MONTH(B10) -> 12 | AC10: =YEAR(B10) -> 2025
B11: 46017 | I11: =IF(Job_Cards[[#This Row],[Customer Name]]="",I10,"") -> Paid | J11: B008080900252 | K11: =_xlfn.XLOOKUP(Job_Cards[[#This Row],[Part Code Issued]],'Inventory Check'!$A$3:$A$3000,'Inventory Check'!$B$3:$B$3000,"WRONG Code",0) -> FUEL FILTER | L11: 1 | M11: 1575 | N11: =M11*L11 -> 1575 | U11: =SUM(O11:T11) -> 0 | V11: =U11*0.18 -> 0 | X11: =Job_Cards[[#This Row],[GST on Lobour]]+Job_Cards[[#This Row],[Total Labour]]+Job_Cards[[#This Row],[Part Value]] -> 1575 | AA11: =DAY(B11) -> 26 | AB11: =MONTH(B11) -> 12 | AC11: =YEAR(B11) -> 2025
A12: 21/12/2025 | B12: 46012 | C12: 2054 | D12: MRP PUBLIC SCHOOL SINGERA MARDAH | E12: 9214250492 | F12: UP61BT6637 | G12: T1 | H12: School | I12: Paid | N12: =M12*L12 -> 0 | P12: 500 | U12: =SUM(O12:T12) -> 500 | V12: =U12*0.18 -> 90 | X12: =Job_Cards[[#This Row],[GST on Lobour]]+Job_Cards[[#This Row],[Total Labour]]+Job_Cards[[#This Row],[Part Value]] -> 590 | AA12: =DAY(B12) -> 21 | AB12: =MONTH(B12) -> 12 | AC12: =YEAR(B12) -> 2025
A13: 23/12/2025 | B13: 46014 | C13: 2055 | D13: SUNBEAM SCHOOL MAHARAJGANJ | E13: 9839174305 | F13: UP61BT6560 | G13: T1 | H13: School | I13: Paid | J13: B008081803210 | K13: =_xlfn.XLOOKUP(Job_Cards[[#This Row],[Part Code Issued]],'Inventory Check'!$A$3:$A$3000,'Inventory Check'!$B$3:$B$3000,"WRONG Code",0) -> Oil Filter | L13: 1 | M13: 359 | N13: =M13*L13 -> 359 | O13: 900 | U13: =SUM(O13:T13) -> 900 | V13: =U13*0.18 -> 162 | X13: =Job_Cards[[#This Row],[GST on Lobour]]+Job_Cards[[#This Row],[Total Labour]]+Job_Cards[[#This Row],[Part Value]] -> 1421 | AA13: =DAY(B13) -> 23 | AB13: =MONTH(B13) -> 12 | AC13: =YEAR(B13) -> 2025
B14: 46014 | I14: =IF(Job_Cards[[#This Row],[Customer Name]]="",I13,"") -> Paid | J14: Gulf Force BS VI (6.5L) | K14: =_xlfn.XLOOKUP(Job_Cards[[#This Row],[Part Code Issued]],'Inventory Check'!$A$3:$A$3000,'Inventory Check'!$B$3:$B$3000,"WRONG Code",0) -> Gulf Force BS VI (6.5L) | L14: 1 | M14: 2080 | N14: =M14*L14 -> 2080 | U14: =SUM(O14:T14) -> 0 | V14: =U14*0.18 -> 0 | X14: =Job_Cards[[#This Row],[GST on Lobour]]+Job_Cards[[#This Row],[Total Labour]]+Job_Cards[[#This Row],[Part Value]] -> 2080 | AA14: =DAY(B14) -> 23 | AB14: =MONTH(B14) -> 12 | AC14: =YEAR(B14) -> 2025
A15: 23/12/2025 | B15: 46014 | C15: 2056 | D15: SUNBEAM SCHOOL DILDAR NAGAR GZP | E15: 7267059150 | F15: UP61AT9814 | G15: T1 | H15: School | I15: Paid | J15: B008081803210 | K15: =_xlfn.XLOOKUP(Job_Cards[[#This Row],[Part Code Issued]],'Inventory Check'!$A$3:$A$3000,'Inventory Check'!$B$3:$B$3000,"WRONG Code",0) -> Oil Filter | L15: 1 | M15: 359 | N15: =M15*L15 -> 359 | O15: 900 | U15: =SUM(O15:T15) -> 900 | V15: =U15*0.18 -> 162 | X15: =Job_Cards[[#This Row],[GST on Lobour]]+Job_Cards[[#This Row],[Total Labour]]+Job_Cards[[#This Row],[Part Value]] -> 1421 | AA15: =DAY(B15) -> 23 | AB15: =MONTH(B15) -> 12 | AC15: =YEAR(B15) -> 2025
B16: 46014 | I16: =IF(Job_Cards[[#This Row],[Customer Name]]="",I15,"") -> Paid | J16: Gulf Force BS VI (6.5L) | K16: =_xlfn.XLOOKUP(Job_Cards[[#This Row],[Part Code Issued]],'Inventory Check'!$A$3:$A$3000,'Inventory Check'!$B$3:$B$3000,"WRONG Code",0) -> Gulf Force BS VI (6.5L) | L16: 1 | M16: 2080 | N16: =M16*L16 -> 2080 | U16: =SUM(O16:T16) -> 0 | V16: =U16*0.18 -> 0 | X16: =Job_Cards[[#This Row],[GST on Lobour]]+Job_Cards[[#This Row],[Total Labour]]+Job_Cards[[#This Row],[Part Value]] -> 2080 | AA16: =DAY(B16) -> 23 | AB16: =MONTH(B16) -> 12 | AC16: =YEAR(B16) -> 2025
B17: 46014 | I17: =IF(Job_Cards[[#This Row],[Customer Name]]="",I16,"") -> Paid | J17: B008080900252 | K17: =_xlfn.XLOOKUP(Job_Cards[[#This Row],[Part Code Issued]],'Inventory Check'!$A$3:$A$3000,'Inventory Check'!$B$3:$B$3000,"WRONG Code",0) -> FUEL FILTER | L17: 1 | M17: 1575 | N17: =M17*L17 -> 1575 | U17: =SUM(O17:T17) -> 0 | V17: =U17*0.18 -> 0 | X17: =Job_Cards[[#This Row],[GST on Lobour]]+Job_Cards[[#This Row],[Total Labour]]+Job_Cards[[#This Row],[Part Value]] -> 1575 | AA17: =DAY(B17) -> 23 | AB17: =MONTH(B17) -> 12 | AC17: =YEAR(B17) -> 2025
A18: 24/12/2025 | B18: 46015 | C18: 2057 | D18: GRUKUL INTER COLLEGE ZAMANIYA | G18: T1 | H18: School | I18: Counter Sale | J18: Gulf Force AdBlue (20 L) | K18: =_xlfn.XLOOKUP(Job_Cards[[#This Row],[Part Code Issued]],'Inventory Check'!$A$3:$A$3000,'Inventory Check'!$B$3:$B$3000,"WRONG Code",0) -> Gulf Force AdBlue (20 L) | L18: 1 | M18: 1480 | N18: =M18*L18 -> 1480 | U18: =SUM(O18:T18) -> 0 | V18: =U18*0.18 -> 0 | X18: =Job_Cards[[#This Row],[GST on Lobour]]+Job_Cards[[#This Row],[Total Labour]]+Job_Cards[[#This Row],[Part Value]] -> 1480 | AA18: =DAY(B18) -> 24 | AB18: =MONTH(B18) -> 12 | AC18: =YEAR(B18) -> 2025
B19: 46015 | I19: =IF(Job_Cards[[#This Row],[Customer Name]]="",I18,"") -> Counter Sale | J19: Gulf Force AdBlue (10) | K19: =_xlfn.XLOOKUP(Job_Cards[[#This Row],[Part Code Issued]],'Inventory Check'!$A$3:$A$3000,'Inventory Check'!$B$3:$B$3000,"WRONG Code",0) -> Gulf Force AdBlue (10) | L19: 1 | M19: 770 | N19: =M19*L19 -> 770 | U19: =SUM(O19:T19) -> 0 | V19: =U19*0.18 -> 0 | X19: =Job_Cards[[#This Row],[GST on Lobour]]+Job_Cards[[#This Row],[Total Labour]]+Job_Cards[[#This Row],[Part Value]] -> 770 | AA19: =DAY(B19) -> 24 | AB19: =MONTH(B19) -> 12 | AC19: =YEAR(B19) -> 2025
B20: 46015 | I20: =IF(Job_Cards[[#This Row],[Customer Name]]="",I19,"") -> Counter Sale | J20: B001809931010 | K20: =_xlfn.XLOOKUP(Job_Cards[[#This Row],[Part Code Issued]],'Inventory Check'!$A$3:$A$3000,'Inventory Check'!$B$3:$B$3000,"WRONG Code",0) -> CLUTCH SPRING | L20: 1 | M20: 17 | N20: =M20*L20 -> 17 | U20: =SUM(O20:T20) -> 0 | V20: =U20*0.18 -> 0 | X20: =Job_Cards[[#This Row],[GST on Lobour]]+Job_Cards[[#This Row],[Total Labour]]+Job_Cards[[#This Row],[Part Value]] -> 17 | AA20: =DAY(B20) -> 24 | AB20: =MONTH(B20) -> 12 | AC20: =YEAR(B20) -> 2025
B21: 46015 | I21: =IF(Job_Cards[[#This Row],[Customer Name]]="",I20,"") -> Counter Sale | J21: B008543220044 | K21: =_xlfn.XLOOKUP(Job_Cards[[#This Row],[Part Code Issued]],'Inventory Check'!$A$3:$A$3000,'Inventory Check'!$B$3:$B$3000,"WRONG Code",0) -> Bumper Rubber | L21: 1 | M21: 142 | N21: =M21*L21 -> 142 | U21: =SUM(O21:T21) -> 0 | V21: =U21*0.18 -> 0 | X21: =Job_Cards[[#This Row],[GST on Lobour]]+Job_Cards[[#This Row],[Total Labour]]+Job_Cards[[#This Row],[Part Value]] -> 142 | AA21: =DAY(B21) -> 24 | AB21: =MONTH(B21) -> 12 | AC21: =YEAR(B21) -> 2025
A22: 25/12/2025 | B22: 46016 | C22: 2058 | D22: PRAMANAND MANORMA DEVI KASHIMABAD | E22: 9415970915 | F22: UP61BT0206 | G22: T1 | H22: School | I22: Paid | J22: Gulf Force BS VI (6.5L) | K22: =_xlfn.XLOOKUP(Job_Cards[[#This Row],[Part Code Issued]],'Inventory Check'!$A$3:$A$3000,'Inventory Check'!$B$3:$B$3000,"WRONG Code",0) -> Gulf Force BS VI (6.5L) | L22: 1 | M22: 2080 | N22: =M22*L22 -> 2080 | O22: 850 | U22: =SUM(O22:T22) -> 850 | V22: =U22*0.18 -> 153 | X22: =Job_Cards[[#This Row],[GST on Lobour]]+Job_Cards[[#This Row],[Total Labour]]+Job_Cards[[#This Row],[Part Value]] -> 3083 | AA22: =DAY(B22) -> 25 | AB22: =MONTH(B22) -> 12 | AC22: =YEAR(B22) -> 2025
B23: 46016 | I23: =IF(Job_Cards[[#This Row],[Customer Name]]="",I22,"") -> Paid | J23: B008081803210 | K23: =_xlfn.XLOOKUP(Job_Cards[[#This Row],[Part Code Issued]],'Inventory Check'!$A$3:$A$3000,'Inventory Check'!$B$3:$B$3000,"WRONG Code",0) -> Oil Filter | L23: 1 | M23: 359 | N23: =M23*L23 -> 359 | U23: =SUM(O23:T23) -> 0 | V23: =U23*0.18 -> 0 | X23: =Job_Cards[[#This Row],[GST on Lobour]]+Job_Cards[[#This Row],[Total Labour]]+Job_Cards[[#This Row],[Part Value]] -> 359 | AA23: =DAY(B23) -> 25 | AB23: =MONTH(B23) -> 12 | AC23: =YEAR(B23) -> 2025
A24: 25/12/2025 | B24: 46016 | C24: 2059 | D24: SHAVITRI BALIKA INTER COLLEGE | E24: 6306615783 | F24: UP67AT6861 | G24: T1 | H24: School | I24: Paid | J24: Fuse | K24: =_xlfn.XLOOKUP(Job_Cards[[#This Row],[Part Code Issued]],'Inventory Check'!$A$3:$A$3000,'Inventory Check'!$B$3:$B$3000,"WRONG Code",0) -> Electric Fuse | L24: 2 | M24: 140 | N24: =M24*L24 -> 280 | O24: 250 | U24: =SUM(O24:T24) -> 250 | V24: =U24*0.18 -> 45 | X24: =Job_Cards[[#This Row],[GST on Lobour]]+Job_Cards[[#This Row],[Total Labour]]+Job_Cards[[#This Row],[Part Value]] -> 575 | AA24: =DAY(B24) -> 25 | AB24: =MONTH(B24) -> 12 | AC24: =YEAR(B24) -> 2025
A25: 25/12/2025 | B25: 46016 | C25: 2060 | D25: LITTE BALLASOME SCHOOL | E25: 9565916094 | F25: UP61CT3487 | G25: Trax | H25: School | I25: Free Service | J25: Gulf Force BS VI (6.5L) | K25: =_xlfn.XLOOKUP(Job_Cards[[#This Row],[Part Code Issued]],'Inventory Check'!$A$3:$A$3000,'Inventory Check'!$B$3:$B$3000,"WRONG Code",0) -> Gulf Force BS VI (6.5L) | L25: 1 | M25: 2080 | N25: =M25*L25 -> 2080 | U25: =SUM(O25:T25) -> 0 | V25: =U25*0.18 -> 0 | X25: =Job_Cards[[#This Row],[GST on Lobour]]+Job_Cards[[#This Row],[Total Labour]]+Job_Cards[[#This Row],[Part Value]] -> 2080 | AA25: =DAY(B25) -> 25 | AB25: =MONTH(B25) -> 12 | AC25: =YEAR(B25) -> 2025
B26: 46016 | I26: =IF(Job_Cards[[#This Row],[Customer Name]]="",I25,"") -> Free Service | J26: B008081803210 | K26: =_xlfn.XLOOKUP(Job_Cards[[#This Row],[Part Code Issued]],'Inventory Check'!$A$3:$A$3000,'Inventory Check'!$B$3:$B$3000,"WRONG Code",0) -> Oil Filter | L26: 1 | M26: 359 | N26: =M26*L26 -> 359 | U26: =SUM(O26:T26) -> 0 | V26: =U26*0.18 -> 0 | X26: =Job_Cards[[#This Row],[GST on Lobour]]+Job_Cards[[#This Row],[Total Labour]]+Job_Cards[[#This Row],[Part Value]] -> 359 | AA26: =DAY(B26) -> 25 | AB26: =MONTH(B26) -> 12 | AC26: =YEAR(B26) -> 2025
A27: 28/12/2025 | B27: 46019 | C27: 2061 | D27: RAGHUNANDAN KUSHANDEV PG COLLEGE | E27: 9415870147 | F27: UP61BT7549 | G27: T1 | H27: School | I27: Paid | J27: T006865864130 | K27: =_xlfn.XLOOKUP(Job_Cards[[#This Row],[Part Code Issued]],'Inventory Check'!$A$3:$A$3000,'Inventory Check'!$B$3:$B$3000,"WRONG Code",0) -> KING PIN SET | L27: 1 | M27: 2438 | N27: =M27*L27 -> 2438 | O27: 2900 | P27: 150 | U27: =SUM(O27:T27) -> 3050 | V27: =U27*0.18 -> 549 | X27: =Job_Cards[[#This Row],[GST on Lobour]]+Job_Cards[[#This Row],[Total Labour]]+Job_Cards[[#This Row],[Part Value]] -> 6037 | AA27: =DAY(B27) -> 28 | AB27: =MONTH(B27) -> 12 | AC27: =YEAR(B27) -> 2025
B28: 46019 | I28: =IF(Job_Cards[[#This Row],[Customer Name]]="",I27,"") -> Paid | J28: GREASE | K28: =_xlfn.XLOOKUP(Job_Cards[[#This Row],[Part Code Issued]],'Inventory Check'!$A$3:$A$3000,'Inventory Check'!$B$3:$B$3000,"WRONG Code",0) -> GREASE | L28: 1 | M28: 555 | N28: =M28*L28 -> 555 | U28: =SUM(O28:T28) -> 0 | V28: =U28*0.18 -> 0 | X28: =Job_Cards[[#This Row],[GST on Lobour]]+Job_Cards[[#This Row],[Total Labour]]+Job_Cards[[#This Row],[Part Value]] -> 555 | AA28: =DAY(B28) -> 28 | AB28: =MONTH(B28) -> 12 | AC28: =YEAR(B28) -> 2025
B29: 46019 | I29: =IF(Job_Cards[[#This Row],[Customer Name]]="",I28,"") -> Paid | J29: B008239970147 | K29: =_xlfn.XLOOKUP(Job_Cards[[#This Row],[Part Code Issued]],'Inventory Check'!$A$3:$A$3000,'Inventory Check'!$B$3:$B$3000,"WRONG Code",0) -> Oil Seal For Fr. Exle | L29: 2 | M29: 85 | N29: =M29*L29 -> 170 | U29: =SUM(O29:T29) -> 0 | V29: =U29*0.18 -> 0 | X29: =Job_Cards[[#This Row],[GST on Lobour]]+Job_Cards[[#This Row],[Total Labour]]+Job_Cards[[#This Row],[Part Value]] -> 170 | AA29: =DAY(B29) -> 28 | AB29: =MONTH(B29) -> 12 | AC29: =YEAR(B29) -> 2025
B30: 46019 | I30: =IF(Job_Cards[[#This Row],[Customer Name]]="",I29,"") -> Paid | J30: T00886330053 | K30: =_xlfn.XLOOKUP(Job_Cards[[#This Row],[Part Code Issued]],'Inventory Check'!$A$3:$A$3000,'Inventory Check'!$B$3:$B$3000,"WRONG Code",0) -> WRONG Code | L30: 1 | M30: 2809 | N30: =M30*L30 -> 2809 | U30: =SUM(O30:T30) -> 0 | V30: =U30*0.18 -> 0 | X30: =Job_Cards[[#This Row],[GST on Lobour]]+Job_Cards[[#This Row],[Total Labour]]+Job_Cards[[#This Row],[Part Value]] -> 2809 | AA30: =DAY(B30) -> 28 | AB30: =MONTH(B30) -> 12 | AC30: =YEAR(B30) -> 2025
B31: 46019 | I31: =IF(Job_Cards[[#This Row],[Customer Name]]="",I30,"") -> Paid | J31: T006869810505 | K31: =_xlfn.XLOOKUP(Job_Cards[[#This Row],[Part Code Issued]],'Inventory Check'!$A$3:$A$3000,'Inventory Check'!$B$3:$B$3000,"WRONG Code",0) -> Taper Roller Bearing | L31: 1 | M31: 450 | N31: =M31*L31 -> 450 | U31: =SUM(O31:T31) -> 0 | V31: =U31*0.18 -> 0 | X31: =Job_Cards[[#This Row],[GST on Lobour]]+Job_Cards[[#This Row],[Total Labour]]+Job_Cards[[#This Row],[Part Value]] -> 450 | AA31: =DAY(B31) -> 28 | AB31: =MONTH(B31) -> 12 | AC31: =YEAR(B31) -> 2025
B32: 46019 | I32: =IF(Job_Cards[[#This Row],[Customer Name]]="",I31,"") -> Paid | J32: 501349 | K32: =_xlfn.XLOOKUP(Job_Cards[[#This Row],[Part Code Issued]],'Inventory Check'!$A$3:$A$3000,'Inventory Check'!$B$3:$B$3000,"WRONG Code",0) -> WRONG Code | L32: 1 | M32: 675 | N32: =M32*L32 -> 675 | U32: =SUM(O32:T32) -> 0 | V32: =U32*0.18 -> 0 | X32: =Job_Cards[[#This Row],[GST on Lobour]]+Job_Cards[[#This Row],[Total Labour]]+Job_Cards[[#This Row],[Part Value]] -> 675 | Z32: 550 | AA32: =DAY(B32) -> 28 | AB32: =MONTH(B32) -> 12 | AC32: =YEAR(B32) -> 2025
B33: 46019 | I33: =IF(Job_Cards[[#This Row],[Customer Name]]="",I32,"") -> Paid | J33: T006865864330 | K33: =_xlfn.XLOOKUP(Job_Cards[[#This Row],[Part Code Issued]],'Inventory Check'!$A$3:$A$3000,'Inventory Check'!$B$3:$B$3000,"WRONG Code",0) -> OIL SEAL KIT | L33: 1 | M33: 492 | N33: =M33*L33 -> 492 | U33: =SUM(O33:T33) -> 0 | V33: =U33*0.18 -> 0 | X33: =Job_Cards[[#This Row],[GST on Lobour]]+Job_Cards[[#This Row],[Total Labour]]+Job_Cards[[#This Row],[Part Value]] -> 492 | AA33: =DAY(B33) -> 28 | AB33: =MONTH(B33) -> 12 | AC33: =YEAR(B33) -> 2025
B34: 46019 | I34: =IF(Job_Cards[[#This Row],[Customer Name]]="",I33,"") -> Paid | J34: Fuse | K34: =_xlfn.XLOOKUP(Job_Cards[[#This Row],[Part Code Issued]],'Inventory Check'!$A$3:$A$3000,'Inventory Check'!$B$3:$B$3000,"WRONG Code",0) -> Electric Fuse | L34: 1 | M34: 80 | N34: =M34*L34 -> 80 | U34: =SUM(O34:T34) -> 0 | V34: =U34*0.18 -> 0 | X34: =Job_Cards[[#This Row],[GST on Lobour]]+Job_Cards[[#This Row],[Total Labour]]+Job_Cards[[#This Row],[Part Value]] -> 80 | AA34: =DAY(B34) -> 28 | AB34: =MONTH(B34) -> 12 | AC34: =YEAR(B34) -> 2025
A35: 29/12/2025 | B35: 46020 | C35: 2062 | D35: G. R. Tour & Travels | E35: 7800392363 | F35: UP61CT1985 | G35: T1 | H35: Taxi | I35: Paid | J35: B008041840025 | K35: =_xlfn.XLOOKUP(Job_Cards[[#This Row],[Part Code Issued]],'Inventory Check'!$A$3:$A$3000,'Inventory Check'!$B$3:$B$3000,"WRONG Code",0) -> FUEL FILTER | L35: 1 | M35: 1060 | N35: =M35*L35 -> 1060 | O35: 850 | U35: =SUM(O35:T35) -> 850 | V35: =U35*0.18 -> 153 | X35: =Job_Cards[[#This Row],[GST on Lobour]]+Job_Cards[[#This Row],[Total Labour]]+Job_Cards[[#This Row],[Part Value]] -> 2063 | AA35: =DAY(B35) -> 29 | AB35: =MONTH(B35) -> 12 | AC35: =YEAR(B35) -> 2025
B36: 46020 | I36: =IF(Job_Cards[[#This Row],[Customer Name]]="",I35,"") -> Paid | J36: B008041840125 | K36: =_xlfn.XLOOKUP(Job_Cards[[#This Row],[Part Code Issued]],'Inventory Check'!$A$3:$A$3000,'Inventory Check'!$B$3:$B$3000,"WRONG Code",0) -> FUEL FILTER | L36: 1 | M36: 711 | N36: =M36*L36 -> 711 | U36: =SUM(O36:T36) -> 0 | V36: =U36*0.18 -> 0 | X36: =Job_Cards[[#This Row],[GST on Lobour]]+Job_Cards[[#This Row],[Total Labour]]+Job_Cards[[#This Row],[Part Value]] -> 711 | AA36: =DAY(B36) -> 29 | AB36: =MONTH(B36) -> 12 | AC36: =YEAR(B36) -> 2025
B37: 46020 | I37: =IF(Job_Cards[[#This Row],[Customer Name]]="",I36,"") -> Paid | J37: B008081803210 | K37: =_xlfn.XLOOKUP(Job_Cards[[#This Row],[Part Code Issued]],'Inventory Check'!$A$3:$A$3000,'Inventory Check'!$B$3:$B$3000,"WRONG Code",0) -> Oil Filter | L37: 1 | M37: 359 | N37: =M37*L37 -> 359 | U37: =SUM(O37:T37) -> 0 | V37: =U37*0.18 -> 0 | X37: =Job_Cards[[#This Row],[GST on Lobour]]+Job_Cards[[#This Row],[Total Labour]]+Job_Cards[[#This Row],[Part Value]] -> 359 | AA37: =DAY(B37) -> 29 | AB37: =MONTH(B37) -> 12 | AC37: =YEAR(B37) -> 2025
B38: 46020 | I38: =IF(Job_Cards[[#This Row],[Customer Name]]="",I37,"") -> Paid | J38: Gulf Force AdBlue (20 L) | K38: =_xlfn.XLOOKUP(Job_Cards[[#This Row],[Part Code Issued]],'Inventory Check'!$A$3:$A$3000,'Inventory Check'!$B$3:$B$3000,"WRONG Code",0) -> Gulf Force AdBlue (20 L) | L38: 1 | M38: 1480 | N38: =M38*L38 -> 1480 | U38: =SUM(O38:T38) -> 0 | V38: =U38*0.18 -> 0 | X38: =Job_Cards[[#This Row],[GST on Lobour]]+Job_Cards[[#This Row],[Total Labour]]+Job_Cards[[#This Row],[Part Value]] -> 1480 | AA38: =DAY(B38) -> 29 | AB38: =MONTH(B38) -> 12 | AC38: =YEAR(B38) -> 2025
B39: 46020 | I39: =IF(Job_Cards[[#This Row],[Customer Name]]="",I38,"") -> Paid | J39: Gulf Force BS VI (6.5L) | K39: =_xlfn.XLOOKUP(Job_Cards[[#This Row],[Part Code Issued]],'Inventory Check'!$A$3:$A$3000,'Inventory Check'!$B$3:$B$3000,"WRONG Code",0) -> Gulf Force BS VI (6.5L) | L39: 1 | M39: 2080 | N39: =M39*L39 -> 2080 | U39: =SUM(O39:T39) -> 0 | V39: =U39*0.18 -> 0 | X39: =Job_Cards[[#This Row],[GST on Lobour]]+Job_Cards[[#This Row],[Total Labour]]+Job_Cards[[#This Row],[Part Value]] -> 2080 | AA39: =DAY(B39) -> 29 | AB39: =MONTH(B39) -> 12 | AC39: =YEAR(B39) -> 2025
A40: 29/12/2025 | B40: 46020 | C40: 2063 | D40: Sunbeem School Dehwal Dildarnagar | E40: 8545824480 | F40: UP61CT2705 | G40: T1 | H40: School | I40: Free Service | J40: Gulf Force BS VI (6.5L) | K40: =_xlfn.XLOOKUP(Job_Cards[[#This Row],[Part Code Issued]],'Inventory Check'!$A$3:$A$3000,'Inventory Check'!$B$3:$B$3000,"WRONG Code",0) -> Gulf Force BS VI (6.5L) | L40: 1 | M40: 2080 | N40: =M40*L40 -> 2080 | U40: =SUM(O40:T40) -> 0 | V40: =U40*0.18 -> 0 | X40: =Job_Cards[[#This Row],[GST on Lobour]]+Job_Cards[[#This Row],[Total Labour]]+Job_Cards[[#This Row],[Part Value]] -> 2080 | AA40: =DAY(B40) -> 29 | AB40: =MONTH(B40) -> 12 | AC40: =YEAR(B40) -> 2025
...

Sheet Daily report
A3: Parts PURCHASED
A5: Year | B5: 2026
A7: Sum of MRP | B7: Month
A8: Purchase from | B8: 1 | C8: 2 | D8: 3 | E8: 4 | F8: 5 | G8: 6 | H8: 7
A9: VNS.GAPL | B9: 40182 | C9: 77364 | D9: 157695 | E9: 340208 | F9: 43321 | G9: 72808 | H9: 52759
A10: Sanjay Panday | B10: 28376
A11: Purchase Gzp | B11: 65 | D11: 100 | F11: 95 | G11: 360 | H11: 330
A12: GZP. SWB | F12: 580 | G12: 65 | H12: 1475
A13: Grand Total | B13: 68623 | C13: 77364 | D13: 157795 | E13: 340208 | F13: 43996 | G13: 73233 | H13: 54564
A17: Parts SOLD
A20: Year | B20: (Multiple Items)
A22: Sum of Part Value | B22: Month
A23: Type Of Service | B23: 1 | C23: 12 | D23: 2 | E23: 6 | F23: 4 | G23: 7 | H23: 3 | I23: 5
A24: Free Service | B24: 55753 | C24: 63346 | D24: 89603 | E24: 72013 | F24: 88245 | G24: 22977 | H24: 138820 | I24: 38451
A25: Paid | B25: 70002 | C25: 38305 | D25: 109639.5 | E25: 286380 | F25: 105091 | G25: 94023 | H25: 121786 | I25: 125242
A26: Counter Sale | B26: 40062 | C26: 2409 | D26: 18088 | E26: 28732 | F26: 37856 | G26: 30532 | H26: 37780 | I26: 11160
A27: Breakdown | F27: 3876
A28: Grand Total | B28: 165817 | C28: 104060 | D28: 217330.5 | E28: 387125 | F28: 235068 | G28: 147532 | H28: 298386 | I28: 174853
A32: Daily Report
A34: Year | B34: 2026
A36: Count of Customer Name | B36: Month
A37: Type Of Service | B37: 4 | C37: 5 | D37: 6 | E37: Grand Total
A38: Free Service | B38: 19 | C38: 13 | D38: 18 | E38: 50
A39: Paid | B39: 25 | C39: 30 | D39: 39 | E39: 94
A40: Counter Sale | B40: 15 | C40: 10 | D40: 18 | E40: 43
A41: Breakdown | B41: 3 | E41: 3
A42: Grand Total | B42: 62 | C42: 53 | D42: 75 | E42: 190

Sheet Spare Part IN
A1: Purchase from | B1: Date In | C1: Challan/Invoice Number | D1: Part Code | E1: Part Description | F1: Qty In | G1: Rack No | H1: MRP | I1: Stock Value | J1: Month | K1: Year
I2: =Parts_Purchase[[#This Row],[Qty In]]*Parts_Purchase[[#This Row],[MRP]] -> 0
A3: VNS.GAPL | B3: 46000 | D3: T006868101716 | E3: Side Miror RH | F3: 1 | G3: 46 | H3: 2936 | I3: =Parts_Purchase[[#This Row],[Qty In]]*Parts_Purchase[[#This Row],[MRP]] -> 2936 | J3: =MONTH(B3) -> 12 | K3: =YEAR(B3) -> 2025
A4: VNS.GAPL | B4: 46000 | D4: T006865862431 | E4: SHIFTING DOM KIT | F4: 1 | G4: 39 | H4: 8339 | I4: =Parts_Purchase[[#This Row],[Qty In]]*Parts_Purchase[[#This Row],[MRP]] -> 8339 | J4: =MONTH(B4) -> 12 | K4: =YEAR(B4) -> 2025
A5: VNS.GAPL | B5: 46000 | D5: B001809931010 | E5: CLUTCH SPRING | F5: 2 | G5: 63 | H5: 17 | I5: =Parts_Purchase[[#This Row],[Qty In]]*Parts_Purchase[[#This Row],[MRP]] -> 34 | J5: =MONTH(B5) -> 12 | K5: =YEAR(B5) -> 2025
A6: VNS.GAPL | B6: 46000 | D6: B006017400335 | E6: REAR DOOR LOCK (TRAVELLER) | F6: 1 | G6: 55C | H6: 643 | I6: =Parts_Purchase[[#This Row],[Qty In]]*Parts_Purchase[[#This Row],[MRP]] -> 643 | J6: =MONTH(B6) -> 12 | K6: =YEAR(B6) -> 2025
A7: VNS.GAPL | B7: 46000 | D7: B006017202035 | E7: Cab Door Latch Assembly RH | F7: 2 | G7: 55C | H7: 592 | I7: =Parts_Purchase[[#This Row],[Qty In]]*Parts_Purchase[[#This Row],[MRP]] -> 1184 | J7: =MONTH(B7) -> 12 | K7: =YEAR(B7) -> 2025 | L7: *
A8: VNS.GAPL | B8: 46000 | D8: T006867500184 | E8: BONNET LATCH ASSY | F8: 1 | G8: 55C | H8: 268 | I8: =Parts_Purchase[[#This Row],[Qty In]]*Parts_Purchase[[#This Row],[MRP]] -> 268 | J8: =MONTH(B8) -> 12 | K8: =YEAR(B8) -> 2025
A9: VNS.GAPL | B9: 46000 | D9: B008081803210 | E9: Oil Filter | F9: 26 | G9: 18 | H9: 359 | I9: =Parts_Purchase[[#This Row],[Qty In]]*Parts_Purchase[[#This Row],[MRP]] -> 9334 | J9: =MONTH(B9) -> 12 | K9: =YEAR(B9) -> 2025
A10: VNS.GAPL | B10: 46000 | D10: B00868470000210 | E10: SPIN-ON FILTER | F10: 30 | G10: 13 | H10: 655 | I10: =Parts_Purchase[[#This Row],[Qty In]]*Parts_Purchase[[#This Row],[MRP]] -> 19650 | J10: =MONTH(B10) -> 12 | K10: =YEAR(B10) -> 2025
A11: VNS.GAPL | B11: 46000 | D11: Gulf Force BS VI (6.5L) | E11: Gulf Force BS VI (6.5L) | F11: 18 | G11: 1 | H11: 2080 | I11: =Parts_Purchase[[#This Row],[Qty In]]*Parts_Purchase[[#This Row],[MRP]] -> 37440 | J11: =MONTH(B11) -> 12 | K11: =YEAR(B11) -> 2025 | L11: *
A12: VNS.GAPL | B12: 46000 | D12: Suletion Tap | E12: Suletion Tap | F12: 2 | G12: 28 | H12: 25 | I12: =Parts_Purchase[[#This Row],[Qty In]]*Parts_Purchase[[#This Row],[MRP]] -> 50 | J12: =MONTH(B12) -> 12 | K12: =YEAR(B12) -> 2025
A13: VNS.GAPL | B13: 46000 | D13: BALANCING BUSH 19 NO. | E13: BALANCING BUSH 19 NO. | F13: 4 | G13: 29B | H13: 50 | I13: =Parts_Purchase[[#This Row],[Qty In]]*Parts_Purchase[[#This Row],[MRP]] -> 200 | J13: =MONTH(B13) -> 12 | K13: =YEAR(B13) -> 2025
A14: VNS.GAPL | B14: 46000 | D14: BALANCING BUSH 22 NO. | E14: BALANCING BUSH 22 NO. | F14: 4 | G14: 29C | H14: 50 | I14: =Parts_Purchase[[#This Row],[Qty In]]*Parts_Purchase[[#This Row],[MRP]] -> 200 | J14: =MONTH(B14) -> 12 | K14: =YEAR(B14) -> 2025
A15: VNS.GAPL | B15: 46000 | D15: SHOCKAR BUSH 19 NO. | E15: SHOCKAR BUSH 19 NO. | F15: 4 | G15: 29A | H15: 50 | I15: =Parts_Purchase[[#This Row],[Qty In]]*Parts_Purchase[[#This Row],[MRP]] -> 200 | J15: =MONTH(B15) -> 12 | K15: =YEAR(B15) -> 2025
A16: VNS.GAPL | B16: 46000 | D16: SHOCKAR BUSH 22 NO. | E16: SHOCKAR BUSH 22 NO. | F16: 2 | G16: 29C | H16: 50 | I16: =Parts_Purchase[[#This Row],[Qty In]]*Parts_Purchase[[#This Row],[MRP]] -> 100 | J16: =MONTH(B16) -> 12 | K16: =YEAR(B16) -> 2025 | L16: *
A17: VNS.GAPL | B17: 46006 | D17: B008081803210 | E17: Oil Filter | F17: 5 | G17: 18 | H17: 359 | I17: =Parts_Purchase[[#This Row],[Qty In]]*Parts_Purchase[[#This Row],[MRP]] -> 1795 | J17: =MONTH(B17) -> 12 | K17: =YEAR(B17) -> 2025
A18: VNS.GAPL | B18: 46006 | D18: B008080900252 | E18: FUEL FILTER | F18: 5 | G18: 12 | H18: 1575 | I18: =Parts_Purchase[[#This Row],[Qty In]]*Parts_Purchase[[#This Row],[MRP]] -> 7875 | J18: =MONTH(B18) -> 12 | K18: =YEAR(B18) -> 2025
A19: VNS.GAPL | B19: 46006 | D19: B008041840025 | E19: FUEL FILTER | F19: 6 | G19: 14 | H19: 1060 | I19: =Parts_Purchase[[#This Row],[Qty In]]*Parts_Purchase[[#This Row],[MRP]] -> 6360 | J19: =MONTH(B19) -> 12 | K19: =YEAR(B19) -> 2025
A20: VNS.GAPL | B20: 46006 | D20: B008041840125 | E20: FUEL FILTER | F20: 5 | G20: 14 | H20: 711 | I20: =Parts_Purchase[[#This Row],[Qty In]]*Parts_Purchase[[#This Row],[MRP]] -> 3555 | J20: =MONTH(B20) -> 12 | K20: =YEAR(B20) -> 2025 | L20: *
A21: VNS.GAPL | B21: 46006 | D21: T006860940280 | E21: AIR FILTER | F21: 4 | G21: 6 | H21: 1388 | I21: =Parts_Purchase[[#This Row],[Qty In]]*Parts_Purchase[[#This Row],[MRP]] -> 5552 | J21: =MONTH(B21) -> 12 | K21: =YEAR(B21) -> 2025
A22: VNS.GAPL | B22: 46006 | D22: T006860940080 | E22: AIR FILTER | F22: 5 | G22: 11 | H22: 693 | I22: =Parts_Purchase[[#This Row],[Qty In]]*Parts_Purchase[[#This Row],[MRP]] -> 3465 | J22: =MONTH(B22) -> 12 | K22: =YEAR(B22) -> 2025
A23: VNS.GAPL | B23: 46006 | D23: B008540940304 | E23: AIR FILTER | F23: 8 | G23: 21 | H23: 994 | I23: =Parts_Purchase[[#This Row],[Qty In]]*Parts_Purchase[[#This Row],[MRP]] -> 7952 | J23: =MONTH(B23) -> 12 | K23: =YEAR(B23) -> 2025 | L23: *
A24: VNS.GAPL | B24: 46006 | D24: B008680940080 | E24: AIR FILTER | F24: 2 | G24: 6 | H24: 1138 | I24: =Parts_Purchase[[#This Row],[Qty In]]*Parts_Purchase[[#This Row],[MRP]] -> 2276 | J24: =MONTH(B24) -> 12 | K24: =YEAR(B24) -> 2025
A25: VNS.GAPL | B25: 46006 | D25: B008090500011 | E25: Tensioner Assly | F25: 1 | G25: 43 | H25: 1413 | I25: =Parts_Purchase[[#This Row],[Qty In]]*Parts_Purchase[[#This Row],[MRP]] -> 1413 | J25: =MONTH(B25) -> 12 | K25: =YEAR(B25) -> 2025
A26: VNS.GAPL | B26: 46006 | D26: B008089970795 | E26: Poly V Belt 5 Pk 1549 | F26: 3 | G26: 23A | H26: 623 | I26: =Parts_Purchase[[#This Row],[Qty In]]*Parts_Purchase[[#This Row],[MRP]] -> 1869 | J26: =MONTH(B26) -> 12 | K26: =YEAR(B26) -> 2025 | L26: *
A27: VNS.GAPL | B27: 46006 | D27: B008545861843 | E27: KIT LINING SET | F27: 1 | G27: 49 | H27: 1215 | I27: =Parts_Purchase[[#This Row],[Qty In]]*Parts_Purchase[[#This Row],[MRP]] -> 1215 | J27: =MONTH(B27) -> 12 | K27: =YEAR(B27) -> 2025 | L27: *
A28: VNS.GAPL | B28: 46006 | D28: T006865860242 | E28: BRAKE PISTON KIT | F28: 2 | G28: 38 | H28: 2824 | I28: =Parts_Purchase[[#This Row],[Qty In]]*Parts_Purchase[[#This Row],[MRP]] -> 5648 | J28: =MONTH(B28) -> 12 | K28: =YEAR(B28) -> 2025
A29: VNS.GAPL | B29: 46006 | D29: T006865860342 | E29: BRAKE SEAL KIT | F29: 1 | G29: 35C | H29: 3398 | I29: =Parts_Purchase[[#This Row],[Qty In]]*Parts_Purchase[[#This Row],[MRP]] -> 3398 | J29: =MONTH(B29) -> 12 | K29: =YEAR(B29) -> 2025
A30: VNS.GAPL | B30: 46006 | D30: T006865868030 | E30: BRAKE PAD | F30: 5 | G30: 44 | H30: 2296 | I30: =Parts_Purchase[[#This Row],[Qty In]]*Parts_Purchase[[#This Row],[MRP]] -> 11480 | J30: =MONTH(B30) -> 12 | K30: =YEAR(B30) -> 2025
A31: VNS.GAPL | B31: 46006 | D31: B008553200030 | E31: FRONT SHOKER | F31: 1 | G31: 58 | H31: 1000 | I31: =Parts_Purchase[[#This Row],[Qty In]]*Parts_Purchase[[#This Row],[MRP]] -> 1000 | J31: =MONTH(B31) -> 12 | K31: =YEAR(B31) -> 2025
A32: VNS.GAPL | B32: 46006 | D32: T006869810505 | E32: Taper Roller Bearing | F32: 4 | G32: 50 | H32: 405 | I32: =Parts_Purchase[[#This Row],[Qty In]]*Parts_Purchase[[#This Row],[MRP]] -> 1620 | J32: =MONTH(B32) -> 12 | K32: =YEAR(B32) -> 2025
A33: VNS.GAPL | B33: 46006 | D33: B008543210050 | E33: Bimetal Bush with Oil-Groove | F33: 4 | G33: 43 | H33: 295 | I33: =Parts_Purchase[[#This Row],[Qty In]]*Parts_Purchase[[#This Row],[MRP]] -> 1180 | J33: =MONTH(B33) -> 12 | K33: =YEAR(B33) -> 2025 | L33: *
A34: VNS.GAPL | B34: 46006 | D34: A000023022372 | E34: Wheel Joint assly | F34: 4 | G34: 38 | H34: 641 | I34: =Parts_Purchase[[#This Row],[Qty In]]*Parts_Purchase[[#This Row],[MRP]] -> 2564 | J34: =MONTH(B34) -> 12 | K34: =YEAR(B34) -> 2025 | L34: *
A35: VNS.GAPL | B35: 46006 | D35: A000023016982 | E35: Silent Block | F35: 4 | G35: 35S | H35: 113 | I35: =Parts_Purchase[[#This Row],[Qty In]]*Parts_Purchase[[#This Row],[MRP]] -> 452 | J35: =MONTH(B35) -> 12 | K35: =YEAR(B35) -> 2025
A36: VNS.GAPL | B36: 46006 | D36: B008544600005 | E36: Drag Link Assembly (Greaserless TALBROS) | F36: 2 | G36: 34C | H36: 1203 | I36: =Parts_Purchase[[#This Row],[Qty In]]*Parts_Purchase[[#This Row],[MRP]] -> 2406 | J36: =MONTH(B36) -> 12 | K36: =YEAR(B36) -> 2025
A37: VNS.GAPL | B37: 46006 | D37: A000023062902 | E37: Track Rod Assly. (Talbros-Greaserless) | F37: 2 | G37: 34C | H37: 1211 | I37: =Parts_Purchase[[#This Row],[Qty In]]*Parts_Purchase[[#This Row],[MRP]] -> 2422 | J37: =MONTH(B37) -> 12 | K37: =YEAR(B37) -> 2025
A38: VNS.GAPL | B38: 46006 | D38: B008554600006 | E38: Connecting Link (Judo DLX) | F38: 1 | G38: 29 | H38: 1259 | I38: =Parts_Purchase[[#This Row],[Qty In]]*Parts_Purchase[[#This Row],[MRP]] -> 1259 | J38: =MONTH(B38) -> 12 | K38: =YEAR(B38) -> 2025 | L38: *
A39: VNS.GAPL | B39: 46006 | D39: A000053060792 | E39: Bearing Bushes | F39: 2 | G39: 29C | H39: 368 | I39: =Parts_Purchase[[#This Row],[Qty In]]*Parts_Purchase[[#This Row],[MRP]] -> 736 | J39: =MONTH(B39) -> 12 | K39: =YEAR(B39) -> 2025
A40: VNS.GAPL | B40: 46006 | D40: A000053060162 | E40: Rubber Seal | F40: 17 | G40: 35 o | H40: 9 | I40: =Parts_Purchase[[#This Row],[Qty In]]*Parts_Purchase[[#This Row],[MRP]] -> 153 | J40: =MONTH(B40) -> 12 | K40: =YEAR(B40) -> 2025 | L40: *
...

Sheet Inventory Check
A2: Stock Value | B2: =SUM(Table3[[#All],[Stock Value]]) -> 1200553
A3: Part Code | B3: Part Description | C3: Rack No | D3: MRP | E3: Sum of Stock Value | F3: Total Purchased | G3: Total SOLD | H3: In Stock | I3: Stock Value
A4: (blank) | B4: (blank) | C4: (blank) | D4: (blank) | E4: 0 | F4: =SUMIF(Parts_Purchase[[#All],[Part Code]],'Inventory Check'!A4,Parts_Purchase[[#All],[Qty In]]) -> 0 | G4: =SUMIF(Job_Cards[[#All],[Part Code Issued]],'Inventory Check'!A4,Job_Cards[[#All],[Part Qty]]) -> 0 | H4: =F4-G4 -> 0 | I4: =IFERROR(H4*D4,0) -> 0
A5: 01 Inch | B5: Steel Pench | C5: 35 E | D5: 3 | E5: 87 | F5: =SUMIF(Parts_Purchase[[#All],[Part Code]],'Inventory Check'!A5,Parts_Purchase[[#All],[Qty In]]) -> 29 | G5: =SUMIF(Job_Cards[[#All],[Part Code Issued]],'Inventory Check'!A5,Job_Cards[[#All],[Part Qty]]) -> 0 | H5: =F5-G5 -> 29 | I5: =IFERROR(H5*D5,0) -> 87
A6: 22 No. Lock Nut | B6: 22 No. Lock Nut | C6: 35S | D6: 8 | E6: 8 | F6: =SUMIF(Parts_Purchase[[#All],[Part Code]],'Inventory Check'!A6,Parts_Purchase[[#All],[Qty In]]) -> 1 | G6: =SUMIF(Job_Cards[[#All],[Part Code Issued]],'Inventory Check'!A6,Job_Cards[[#All],[Part Qty]]) -> 0 | H6: =F6-G6 -> 1 | I6: =IFERROR(H6*D6,0) -> 8
A7: 22 No. Plain Washer | B7: 22 No. Plain Washer | C7: 35S | D7: 6 | E7: 120 | F7: =SUMIF(Parts_Purchase[[#All],[Part Code]],'Inventory Check'!A7,Parts_Purchase[[#All],[Qty In]]) -> 20 | G7: =SUMIF(Job_Cards[[#All],[Part Code Issued]],'Inventory Check'!A7,Job_Cards[[#All],[Part Qty]]) -> 0 | H7: =F7-G7 -> 20 | I7: =IFERROR(H7*D7,0) -> 120
A8: 5 no. LN key Bolt | B8: 5 no. LN key Bolt | C8: 62 | D8: 30 | E8: 30 | F8: =SUMIF(Parts_Purchase[[#All],[Part Code]],'Inventory Check'!A8,Parts_Purchase[[#All],[Qty In]]) -> 1 | G8: =SUMIF(Job_Cards[[#All],[Part Code Issued]],'Inventory Check'!A8,Job_Cards[[#All],[Part Qty]]) -> 1 | H8: =F8-G8 -> 0 | I8: =IFERROR(H8*D8,0) -> 0
A9: 80W90 | B9: Gear Oil XP 80W90 HP 1Ltr | C9: 9 | D9: 470 | E9: 23500 | F9: =SUMIF(Parts_Purchase[[#All],[Part Code]],'Inventory Check'!A9,Parts_Purchase[[#All],[Qty In]]) -> 50 | G9: =SUMIF(Job_Cards[[#All],[Part Code Issued]],'Inventory Check'!A9,Job_Cards[[#All],[Part Qty]]) -> 27.5 | H9: =F9-G9 -> 22.5 | I9: =IFERROR(H9*D9,0) -> 10575
A10: 80w90 HP 5Ltr | B10: Gear Oil XP 80W90 HP 5Ltr | C10: 10 | D10: 1909 | E10: 3818 | F10: =SUMIF(Parts_Purchase[[#All],[Part Code]],'Inventory Check'!A10,Parts_Purchase[[#All],[Qty In]]) -> 2 | G10: =SUMIF(Job_Cards[[#All],[Part Code Issued]],'Inventory Check'!A10,Job_Cards[[#All],[Part Qty]]) -> 0 | H10: =F10-G10 -> 2 | I10: =IFERROR(H10*D10,0) -> 3818
A11: 85W140 | B11: Gear Oil XP 85W140 HP 1Ltr | C11: 9 | D11: 475 | E11: 14250 | F11: =SUMIF(Parts_Purchase[[#All],[Part Code]],'Inventory Check'!A11,Parts_Purchase[[#All],[Qty In]]) -> 30 | G11: =SUMIF(Job_Cards[[#All],[Part Code Issued]],'Inventory Check'!A11,Job_Cards[[#All],[Part Qty]]) -> 11 | H11: =F11-G11 -> 19 | I11: =IFERROR(H11*D11,0) -> 9025
A12: A000020140142 | B12: Filter Element | C12: 12 | D12: 115 | E12: 1150 | F12: =SUMIF(Parts_Purchase[[#All],[Part Code]],'Inventory Check'!A12,Parts_Purchase[[#All],[Qty In]]) -> 10 | G12: =SUMIF(Job_Cards[[#All],[Part Code Issued]],'Inventory Check'!A12,Job_Cards[[#All],[Part Qty]]) -> 8 | H12: =F12-G12 -> 2 | I12: =IFERROR(H12*D12,0) -> 230
A13: A000023016982 | B13: Silent Block | C13: 35S | D13: 113 | E13: 3164 | F13: =SUMIF(Parts_Purchase[[#All],[Part Code]],'Inventory Check'!A13,Parts_Purchase[[#All],[Qty In]]) -> 28 | G13: =SUMIF(Job_Cards[[#All],[Part Code Issued]],'Inventory Check'!A13,Job_Cards[[#All],[Part Qty]]) -> 24 | H13: =F13-G13 -> 4 | I13: =IFERROR(H13*D13,0) -> 452
A14: A000023020236 | B14: COVER RING | C14: 35G | D14: 11 | E14: 88 | F14: =SUMIF(Parts_Purchase[[#All],[Part Code]],'Inventory Check'!A14,Parts_Purchase[[#All],[Qty In]]) -> 8 | G14: =SUMIF(Job_Cards[[#All],[Part Code Issued]],'Inventory Check'!A14,Job_Cards[[#All],[Part Qty]]) -> 0 | H14: =F14-G14 -> 8 | I14: =IFERROR(H14*D14,0) -> 88
A15: A000023020512 | B15: Thrust Washer | C15: 50B | D15: 236 | E15: 472 | F15: =SUMIF(Parts_Purchase[[#All],[Part Code]],'Inventory Check'!A15,Parts_Purchase[[#All],[Qty In]]) -> 2 | G15: =SUMIF(Job_Cards[[#All],[Part Code Issued]],'Inventory Check'!A15,Job_Cards[[#All],[Part Qty]]) -> 0 | H15: =F15-G15 -> 2 | I15: =IFERROR(H15*D15,0) -> 472
A16: A000023022372 | B16: Wheel Joint assly | C16: 38 | D16: 641 | E16: 25640 | F16: =SUMIF(Parts_Purchase[[#All],[Part Code]],'Inventory Check'!A16,Parts_Purchase[[#All],[Qty In]]) -> 40 | G16: =SUMIF(Job_Cards[[#All],[Part Code Issued]],'Inventory Check'!A16,Job_Cards[[#All],[Part Qty]]) -> 28 | H16: =F16-G16 -> 12 | I16: =IFERROR(H16*D16,0) -> 7692
... A216: ENGINE OIL | B216: ENGINE OIL | C216: 1 | D216: 2288 | E216: 100672 | F216: =SUMIF(Parts_Purchase[[#All],[Part Code]],'Inventory Check'!A216,Parts_Purchase[[#All],[Qty In]]) -> 94 | G216: =SUMIF(Job_Cards[[#All],[Part Code Issued]],'Inventory Check'!A216,Job_Cards[[#All],[Part Qty]]) -> 35 | H216: =F216-G216 -> 59 | I216: =IFERROR(H216*D216,0) -> 134992
D217: 2400 | E217: 120000 | F217: =SUMIF(Parts_Purchase[[#All],[Part Code]],'Inventory Check'!A217,Parts_Purchase[[#All],[Qty In]]) -> 0 | G217: =SUMIF(Job_Cards[[#All],[Part Code Issued]],'Inventory Check'!A217,Job_Cards[[#All],[Part Qty]]) -> 0 | H217: =F217-G217 -> 0 | I217: =IFERROR(H217*D217,0) -> 0
A218: Force Motors Antifreeze Coolant 1 L | B218: Force Motors Antifreeze Coolant 1 L | C218: 7 | D218: 325 | E218: 29250 | F218: =SUMIF(Parts_Purchase[[#All],[Part Code]],'Inventory Check'!A218,Parts_Purchase[[#All],[Qty In]]) -> 90 | G218: =SUMIF(Job_Cards[[#All],[Part Code Issued]],'Inventory Check'!A218,Job_Cards[[#All],[Part Qty]]) -> 56 | H218: =F218-G218 -> 34 | I218: =IFERROR(H218*D218,0) -> 11050
A219: Force Motors Antifreeze Coolant 5 L | B219: Force Motors Antifreeze Coolant 5 L | C219: 10 | D219: 1425 | E219: 39900 | F219: =SUMIF(Parts_Purchase[[#All],[Part Code]],'Inventory Check'!A219,Parts_Purchase[[#All],[Qty In]]) -> 28 | G219: =SUMIF(Job_Cards[[#All],[Part Code Issued]],'Inventory Check'!A219,Job_Cards[[#All],[Part Qty]]) -> 14 | H219: =F219-G219 -> 14 | I219: =IFERROR(H219*D219,0) -> 19950
A220: Fuse | B220: Electric Fuse | C220: 28 | D220: 10 | E220: 80 | F220: =SUMIF(Parts_Purchase[[#All],[Part Code]],'Inventory Check'!A220,Parts_Purchase[[#All],[Qty In]]) -> 8 | G220: =SUMIF(Job_Cards[[#All],[Part Code Issued]],'Inventory Check'!A220,Job_Cards[[#All],[Part Qty]]) -> 8 | H220: =F220-G220 -> 0 | I220: =IFERROR(H220*D220,0) -> 0
A221: Fuse 10 Amp | B221: Fuse 10 Amp | C221: 27 | D221: 5 | E221: 1000 | F221: =SUMIF(Parts_Purchase[[#All],[Part Code]],'Inventory Check'!A221,Parts_Purchase[[#All],[Qty In]]) -> 200 | G221: =SUMIF(Job_Cards[[#All],[Part Code Issued]],'Inventory Check'!A221,Job_Cards[[#All],[Part Qty]]) -> 10 | H221: =F221-G221 -> 190 | I221: =IFERROR(H221*D221,0) -> 950
A222: Fuse 15 Amp | B222: Fuse 15 Amp | C222: 27 | D222: 5 | E222: 1000 | F222: =SUMIF(Parts_Purchase[[#All],[Part Code]],'Inventory Check'!A222,Parts_Purchase[[#All],[Qty In]]) -> 200 | G222: =SUMIF(Job_Cards[[#All],[Part Code Issued]],'Inventory Check'!A222,Job_Cards[[#All],[Part Qty]]) -> 4 | H222: =F222-G222 -> 196 | I222: =IFERROR(H222*D222,0) -> 980
A223: Fuse 20 Amp | B223: Fuse 20 Amp | C223: 27 | D223: 7 | E223: 1400 | F223: =SUMIF(Parts_Purchase[[#All],[Part Code]],'Inventory Check'!A223,Parts_Purchase[[#All],[Qty In]]) -> 200 | G223: =SUMIF(Job_Cards[[#All],[Part Code Issued]],'Inventory Check'!A223,Job_Cards[[#All],[Part Qty]]) -> 12 | H223: =F223-G223 -> 188 | I223: =IFERROR(H223*D223,0) -> 1316
A224: Fuse 25 Amp | B224: Fuse 25 Amp | C224: 27 | D224: 7 | E224: 1400 | F224: =SUMIF(Parts_Purchase[[#All],[Part Code]],'Inventory Check'!A224,Parts_Purchase[[#All],[Qty In]]) -> 200 | G224: =SUMIF(Job_Cards[[#All],[Part Code Issued]],'Inventory Check'!A224,Job_Cards[[#All],[Part Qty]]) -> 5 | H224: =F224-G224 -> 195 | I224: =IFERROR(H224*D224,0) -> 1365
A225: Fuse 30 Amp | B225: Fuse 30 Amp | C225: 27 | D225: 7 | E225: 1400 | F225: =SUMIF(Parts_Purchase[[#All],[Part Code]],'Inventory Check'!A225,Parts_Purchase[[#All],[Qty In]]) -> 200 | G225: =SUMIF(Job_Cards[[#All],[Part Code Issued]],'Inventory Check'!A225,Job_Cards[[#All],[Part Qty]]) -> 0 | H225: =F225-G225 -> 200 | I225: =IFERROR(H225*D225,0) -> 1400
A226: Fuse 60 Amp | B226: Fuse 60 Amp | C226: 28 | D226: 50 | E226: 200 | F226: =SUMIF(Parts_Purchase[[#All],[Part Code]],'Inventory Check'!A226,Parts_Purchase[[#All],[Qty In]]) -> 4 | G226: =SUMIF(Job_Cards[[#All],[Part Code Issued]],'Inventory Check'!A226,Job_Cards[[#All],[Part Qty]]) -> 0 | H226: =F226-G226 -> 4 | I226: =IFERROR(H226*D226,0) -> 200
A227: Fuse Wire | B227: Fuse Wire | C227: 28 | D227: 18 | E227: 360 | F227: =SUMIF(Parts_Purchase[[#All],[Part Code]],'Inventory Check'!A227,Parts_Purchase[[#All],[Qty In]]) -> 20 | G227: =SUMIF(Job_Cards[[#All],[Part Code Issued]],'Inventory Check'!A227,Job_Cards[[#All],[Part Qty]]) -> 0 | H227: =F227-G227 -> 20 | I227: =IFERROR(H227*D227,0) -> 360
A228: Gear Lever Minor Kit | B228: Gear Lever Minor Kit | C228: 1 | D228: 200 | E228: 200 | F228: =SUMIF(Parts_Purchase[[#All],[Part Code]],'Inventory Check'!A228,Parts_Purchase[[#All],[Qty In]]) -> 1 | G228: =SUMIF(Job_Cards[[#All],[Part Code Issued]],'Inventory Check'!A228,Job_Cards[[#All],[Part Qty]]) -> 0 | H228: =F228-G228 -> 1 | I228: =IFERROR(H228*D228,0) -> 200
A229: Gittak Washar | B229: Gittak Washar | C229: 69A | D229: 10 | E229: 660 | F229: =SUMIF(Parts_Purchase[[#All],[Part Code]],'Inventory Check'!A229,Parts_Purchase[[#All],[Qty In]]) -> 66 | G229: =SUMIF(Job_Cards[[#All],[Part Code Issued]],'Inventory Check'!A229,Job_Cards[[#All],[Part Qty]]) -> 21 | H229: =F229-G229 -> 45 | I229: =IFERROR(H229*D229,0) -> 450
... A234: Gulf Force AdBlue (10) | B234: Gulf Force AdBlue (10) | C234: 1 | D234: 770 | E234: 33110 | F234: =SUMIF(Parts_Purchase[[#All],[Part Code]],'Inventory Check'!A234,Parts_Purchase[[#All],[Qty In]]) -> 93 | G234: =SUMIF(Job_Cards[[#All],[Part Code Issued]],'Inventory Check'!A234,Job_Cards[[#All],[Part Qty]]) -> 36 | H234: =F234-G234 -> 57 | I234: =IFERROR(H234*D234,0) -> 43890
D235: 990 | E235: 49500 | F235: =SUMIF(Parts_Purchase[[#All],[Part Code]],'Inventory Check'!A235,Parts_Purchase[[#All],[Qty In]]) -> 0 | G235: =SUMIF(Job_Cards[[#All],[Part Code Issued]],'Inventory Check'!A235,Job_Cards[[#All],[Part Qty]]) -> 0 | H235: =F235-G235 -> 0 | I235: =IFERROR(H235*D235,0) -> 0
A236: Gulf Force AdBlue (20 L) | B236: Gulf Force AdBlue (20 L) | C236: 1 | D236: 1480 | E236: 79920 | F236: =SUMIF(Parts_Purchase[[#All],[Part Code]],'Inventory Check'!A236,Parts_Purchase[[#All],[Qty In]]) -> 104 | G236: =SUMIF(Job_Cards[[#All],[Part Code Issued]],'Inventory Check'!A236,Job_Cards[[#All],[Part Qty]]) -> 64 | H236: =F236-G236 -> 40 | I236: =IFERROR(H236*D236,0) -> 59200
D237: 1920 | E237: 96000 | F237: =SUMIF(Parts_Purchase[[#All],[Part Code]],'Inventory Check'!A237,Parts_Purchase[[#All],[Qty In]]) -> 0 | G237: =SUMIF(Job_Cards[[#All],[Part Code Issued]],'Inventory Check'!A237,Job_Cards[[#All],[Part Qty]]) -> 0 | H237: =F237-G237 -> 0 | I237: =IFERROR(H237*D237,0) -> 0
A238: Gulf Force BS VI (6.5L) | B238: Gulf Force BS VI (6.5L) | C238: 1 | D238: 2080 | E238: 447200 | F238: =SUMIF(Parts_Purchase[[#All],[Part Code]],'Inventory Check'!A238,Parts_Purchase[[#All],[Qty In]]) -> 285 | G238: =SUMIF(Job_Cards[[#All],[Part Code Issued]],'Inventory Check'!A238,Job_Cards[[#All],[Part Qty]]) -> 218 | H238: =F238-G238 -> 67 | I238: =IFERROR(H238*D238,0) -> 139360
D239: 2243 | E239: 157010 | F239: =SUMIF(Parts_Purchase[[#All],[Part Code]],'Inventory Check'!A239,Parts_Purchase[[#All],[Qty In]]) -> 0 | G239: =SUMIF(Job_Cards[[#All],[Part Code Issued]],'Inventory Check'!A239,Job_Cards[[#All],[Part Qty]]) -> 0 | H239: =F239-G239 -> 0 | I239: =IFERROR(H239*D239,0) -> 0
A240: H-1 | B240: Head Light Bulb Force | C240: 28 | D240: 100 | E240: 1000 | F240: =SUMIF(Parts_Purchase[[#All],[Part Code]],'Inventory Check'!A240,Parts_Purchase[[#All],[Qty In]]) -> 10 | G240: =SUMIF(Job_Cards[[#All],[Part Code Issued]],'Inventory Check'!A240,Job_Cards[[#All],[Part Qty]]) -> 1 | H240: =F240-G240 -> 9 | I240: =IFERROR(H240*D240,0) -> 900
A241: H-4 | B241: Bulb 12V 90/100W | C241: 28 | D241: 245 | E241: 2450 | F241: =SUMIF(Parts_Purchase[[#All],[Part Code]],'Inventory Check'!A241,Parts_Purchase[[#All],[Qty In]]) -> 10 | G241: =SUMIF(Job_Cards[[#All],[Part Code Issued]],'Inventory Check'!A241,Job_Cards[[#All],[Part Qty]]) -> 1 | H241: =F241-G241 -> 9 | I241: =IFERROR(H241*D241,0) -> 2205
A242: H-7 | B242: Head Light Bulb | C242: 28 | D242: 210 | E242: 2100 | F242: =SUMIF(Parts_Purchase[[#All],[Part Code]],'Inventory Check'!A242,Parts_Purchase[[#All],[Qty In]]) -> 10 | G242: =SUMIF(Job_Cards[[#All],[Part Code Issued]],'Inventory Check'!A242,Job_Cards[[#All],[Part Qty]]) -> 2 | H242: =F242-G242 -> 8 | I242: =IFERROR(H242*D242,0) -> 1680
A243: Horn Clip | B243: Horn Clip | C243: 28 | D243: 9 | E243: 900 | F243: =SUMIF(Parts_Purchase[[#All],[Part Code]],'Inventory Check'!A243,Parts_Purchase[[#All],[Qty In]]) -> 100 | G243: =SUMIF(Job_Cards[[#All],[Part Code Issued]],'Inventory Check'!A243,Job_Cards[[#All],[Part Qty]]) -> 14 | H243: =F243-G243 -> 86 | I243: =IFERROR(H243*D243,0) -> 774
A244: Hose Clip 02 Inch | B244: Hose Clip 02 Inch | C244: 40 | D244: 25 | E244: 250 | F244: =SUMIF(Parts_Purchase[[#All],[Part Code]],'Inventory Check'!A244,Parts_Purchase[[#All],[Qty In]]) -> 10 | G244: =SUMIF(Job_Cards[[#All],[Part Code Issued]],'Inventory Check'!A244,Job_Cards[[#All],[Part Qty]]) -> 0 | H244: =F244-G244 -> 10 | I244: =IFERROR(H244*D244,0) -> 250
...

Sheet Service Coupon
A1: Free Service Coupon Claim
A3: Workshop Name | B3: Location | C3: Coupon Number | D3: Service Date | E3: Service KMS/Hrs | F3: Vehicle Model | G3: Customer Name | H3: Chassis No | I3: Date for Handover to Varanasi Workshop | J3: Claim Value | K3: Claim Status | L3: Month | M3: Year
A4: Goenka force Ghazipur | B4: Ghazipur | C4: 796369 | D4: 46089 | E4: 69094 | F4: T1 | G4: GVK | H4: P083558 | I4: 46094 | J4: 500 | L4: =MONTH(FSC_Coupon[[#This Row],[Service Date]]) -> 3 | M4: =YEAR(FSC_Coupon[[#This Row],[Service Date]]) -> 2026
A5: Goenka force Ghazipur | B5: Ghazipur | C5: 796158 | D5: 46089 | E5: 71528 | F5: T1 | G5: GVK | H5: P083884 | I5: 46094 | J5: 500 | L5: =MONTH(FSC_Coupon[[#This Row],[Service Date]]) -> 3 | M5: =YEAR(FSC_Coupon[[#This Row],[Service Date]]) -> 2026
A6: Goenka force Ghazipur | B6: Ghazipur | C6: 331201 | D6: 46089 | E6: 2972 | F6: Trax | G6: Inder Singh Kushwaha Sayar Gzp | H6: P001653 | I6: 46094 | J6: 500 | L6: =MONTH(FSC_Coupon[[#This Row],[Service Date]]) -> 3 | M6: =YEAR(FSC_Coupon[[#This Row],[Service Date]]) -> 2026
A7: Goenka force Ghazipur | B7: Ghazipur | C7: 807899 | D7: 46089 | E7: 4098 | F7: T3 | G7: Asha PG College Shikhari Gzp | H7: P003023 | I7: 46094 | J7: 500 | L7: =MONTH(FSC_Coupon[[#This Row],[Service Date]]) -> 3 | M7: =YEAR(FSC_Coupon[[#This Row],[Service Date]]) -> 2026
A8: Goenka force Ghazipur | B8: Ghazipur | C8: 780906 | D8: 46092 | E8: 70324 | F8: T1 | G8: GVK | H8: P083639 | I8: 46094 | J8: 500 | L8: =MONTH(FSC_Coupon[[#This Row],[Service Date]]) -> 3 | M8: =YEAR(FSC_Coupon[[#This Row],[Service Date]]) -> 2026
A9: Goenka force Ghazipur | B9: Ghazipur | C9: 768237 | D9: 46093 | E9: 21761 | F9: T1 | G9: Maa Sharda Children Collage Jalalabad Gzp | H9: P022977 | I9: 46094 | J9: 500 | L9: =MONTH(FSC_Coupon[[#This Row],[Service Date]]) -> 3 | M9: =YEAR(FSC_Coupon[[#This Row],[Service Date]]) -> 2026
A10: Goenka force Ghazipur | B10: Ghazipur | C10: 796539 | D10: 46096 | E10: 72459 | F10: T1 | G10: GVK | H10: P083396 | I10: 46104 | J10: 500 | L10: =MONTH(FSC_Coupon[[#This Row],[Service Date]]) -> 3 | M10: =YEAR(FSC_Coupon[[#This Row],[Service Date]]) -> 2026
A11: Goenka force Ghazipur | B11: Ghazipur | C11: 796598 | D11: 46096 | E11: 71797 | F11: T1 | G11: GVK | H11: P084266 | I11: 46104 | J11: 500 | L11: =MONTH(FSC_Coupon[[#This Row],[Service Date]]) -> 3 | M11: =YEAR(FSC_Coupon[[#This Row],[Service Date]]) -> 2026
A12: Goenka force Ghazipur | B12: Ghazipur | C12: 797756 | D12: 46096 | E12: 73885 | F12: T1 | G12: GVK | H12: P085416 | I12: 46104 | J12: 500 | L12: =MONTH(FSC_Coupon[[#This Row],[Service Date]]) -> 3 | M12: =YEAR(FSC_Coupon[[#This Row],[Service Date]]) -> 2026
A13: Goenka force Ghazipur | B13: Ghazipur | C13: 328544 | D13: 46097 | E13: 8670 | F13: Trax | G13: OM Sai Pb School Kasimabad Gzp | H13: P108712 | I13: 46104 | J13: 500 | L13: =MONTH(FSC_Coupon[[#This Row],[Service Date]]) -> 3 | M13: =YEAR(FSC_Coupon[[#This Row],[Service Date]]) -> 2026
A14: Goenka force Ghazipur | B14: Ghazipur | C14: 796676 | D14: 46099 | E14: 16304 | F14: T1 | G14: Dalims Sunbeem School Jakhania Gzp | H14: P056341 | I14: 46104 | J14: 500 | L14: =MONTH(FSC_Coupon[[#This Row],[Service Date]]) -> 3 | M14: =YEAR(FSC_Coupon[[#This Row],[Service Date]]) -> 2026
A15: Goenka force Ghazipur | B15: Ghazipur | C15: 796557 | D15: 46103 | E15: 71685 | F15: T1 | G15: GVK | H15: P083692 | I15: 46104 | J15: 500 | L15: =MONTH(FSC_Coupon[[#This Row],[Service Date]]) -> 3 | M15: =YEAR(FSC_Coupon[[#This Row],[Service Date]]) -> 2026
... A34: Goenka force Ghazipur | B34: Ghazipur | C34: 780910 | D34: 46112 | E34: 72375 | F34: T1 | G34: GVK | H34: P083890 | I34: 46117 | J34: 500 | L34: =MONTH(FSC_Coupon[[#This Row],[Service Date]]) -> 3 | M34: =YEAR(FSC_Coupon[[#This Row],[Service Date]]) -> 2026
A35: Goenka force Ghazipur | B35: Ghazipur | C35: 333021 | D35: 46117 | E35: 3786 | F35: Trax | G35: International Pb School Sarhula Gzp | H35: P111559 | I35: 14/04/2026 | J35: 500 | L35: =MONTH(FSC_Coupon[[#This Row],[Service Date]]) -> 4 | M35: =YEAR(FSC_Coupon[[#This Row],[Service Date]]) -> 2026
A36: Goenka force Ghazipur | B36: Ghazipur | C36: 798543 | D36: 46117 | E36: 72288 | F36: T1 | G36: GVK | H36: P083308 | I36: 14/04/2026 | J36: 500 | L36: =MONTH(FSC_Coupon[[#This Row],[Service Date]]) -> 4 | M36: =YEAR(FSC_Coupon[[#This Row],[Service Date]]) -> 2026
A37: Goenka force Ghazipur | B37: Ghazipur | C37: 796315 | D37: 46117 | E37: 72150 | F37: T1 | G37: GVK | H37: P083498 | I37: 14/04/2026 | J37: 500 | L37: =MONTH(FSC_Coupon[[#This Row],[Service Date]]) -> 4 | M37: =YEAR(FSC_Coupon[[#This Row],[Service Date]]) -> 2026
A38: Goenka force Ghazipur | B38: Ghazipur | C38: 796523 | D38: 46117 | E38: 70968 | F38: T1 | G38: GVK | H38: P083659 | I38: 14/04/2026 | J38: 500 | L38: =MONTH(FSC_Coupon[[#This Row],[Service Date]]) -> 4 | M38: =YEAR(FSC_Coupon[[#This Row],[Service Date]]) -> 2026
A39: Goenka force Ghazipur | B39: Ghazipur | C39: 334179 | D39: 46117 | E39: 2185 | F39: Trax | G39: City Monteshari School Bhadoura Gzp | H39: P113022 | I39: 14/04/2026 | J39: 500 | L39: =MONTH(FSC_Coupon[[#This Row],[Service Date]]) -> 4 | M39: =YEAR(FSC_Coupon[[#This Row],[Service Date]]) -> 2026
A40: Goenka force Ghazipur | B40: Ghazipur | C40: 795680 | D40: 46122 | E40: 73233 | F40: T1 | G40: GVK | H40: P085503 | I40: 14/04/2026 | J40: 500 | L40: =MONTH(FSC_Coupon[[#This Row],[Service Date]]) -> 4 | M40: =YEAR(FSC_Coupon[[#This Row],[Service Date]]) -> 2026
A41: Goenka force Ghazipur | B41: Ghazipur | C41: 327825 | D41: 46124 | E41: 7791 | F41: Trax | G41: Rameshwaram Gurukulam Medinipur Gzp | H41: P107109 | I41: 14/04/2026 | J41: 0 | L41: =MONTH(FSC_Coupon[[#This Row],[Service Date]]) -> 4 | M41: =YEAR(FSC_Coupon[[#This Row],[Service Date]]) -> 2026
A42: Goenka force Ghazipur | B42: Ghazipur | C42: 331892 | D42: 46124 | E42: 5239 | F42: Trax | G42: Little Blosam Int. School Larpur Gzp | H42: P109874 | I42: 14/04/2026 | J42: 500 | L42: =MONTH(FSC_Coupon[[#This Row],[Service Date]]) -> 4 | M42: =YEAR(FSC_Coupon[[#This Row],[Service Date]]) -> 2026
A43: Goenka force Ghazipur | B43: Ghazipur | C43: 797752 | D43: 46124 | E43: 69310 | F43: T1 | G43: GVK | H43: P085459 | I43: 14/04/2026 | J43: 500 | L43: =MONTH(FSC_Coupon[[#This Row],[Service Date]]) -> 4 | M43: =YEAR(FSC_Coupon[[#This Row],[Service Date]]) -> 2026
A44: Goenka force Ghazipur | B44: Ghazipur | C44: 797320 | D44: 46124 | E44: 70480 | F44: T1 | G44: GVK | H44: P086153 | I44: 14/04/2026 | J44: 500 | L44: =MONTH(FSC_Coupon[[#This Row],[Service Date]]) -> 4 | M44: =YEAR(FSC_Coupon[[#This Row],[Service Date]]) -> 2026
A45: Goenka force Ghazipur | B45: Ghazipur | C45: 796350 | D45: 46124 | E45: 73915 | F45: T1 | G45: GVK | H45: P083460 | I45: 14/04/2026 | J45: 500 | L45: =MONTH(FSC_Coupon[[#This Row],[Service Date]]) -> 4 | M45: =YEAR(FSC_Coupon[[#This Row],[Service Date]]) -> 2026
A46: Goenka force Ghazipur | B46: Ghazipur | C46: 796366 | D46: 46124 | E46: 73055 | F46: T1 | G46: GVK | H46: P083386 | I46: 14/04/2026 | J46: 500 | L46: =MONTH(FSC_Coupon[[#This Row],[Service Date]]) -> 4 | M46: =YEAR(FSC_Coupon[[#This Row],[Service Date]]) -> 2026
... A52: Goenka force Ghazipur | B52: Ghazipur | C52: 328807 | D52: 46132 | E52: 11980 | F52: Trax | G52: BRD Pb School Bikapur Gzp | H52: P001625 | I52: 22/04/2026 | J52: 0 | L52: =MONTH(FSC_Coupon[[#This Row],[Service Date]]) -> 4 | M52: =YEAR(FSC_Coupon[[#This Row],[Service Date]]) -> 2026
A53: Goenka force Ghazipur | B53: Ghazipur | C53: 771339 | D53: 46135 | E53: 14665 | F53: T1 | G53: BRD Pb School Bikapur Gzp | H53: P052689 | I53: 46027 | J53: 500 | L53: =MONTH(FSC_Coupon[[#This Row],[Service Date]]) -> 4 | M53: =YEAR(FSC_Coupon[[#This Row],[Service Date]]) -> 2026
A54: Goenka force Ghazipur | B54: Ghazipur | C54: 807350 | D54: 46136 | E54: 5378 | F54: T1 | G54: S.S. International School Goura Makhadumpur Gzp | H54: P058454 | I54: 46027 | J54: 500 | L54: =MONTH(FSC_Coupon[[#This Row],[Service Date]]) -> 4 | M54: =YEAR(FSC_Coupon[[#This Row],[Service Date]]) -> 2026
A55: Goenka force Ghazipur | B55: Ghazipur | C55: 803683 | D55: 46138 | E55: 8854 | F55: T1 | G55: A.H.M. Pb School Sadiabad Gzp | H55: P057388 | I55: 46027 | J55: 500 | L55: =MONTH(FSC_Coupon[[#This Row],[Service Date]]) -> 4 | M55: =YEAR(FSC_Coupon[[#This Row],[Service Date]]) -> 2026
A56: Goenka force Ghazipur | B56: Ghazipur | C56: 331537 | D56: 46138 | E56: 12185 | F56: Trax | G56: Jagmani Devi Pb School Bhadoura Gzp | H56: P110608 | I56: 46027 | J56: 500 | L56: =MONTH(FSC_Coupon[[#This Row],[Service Date]]) -> 4 | M56: =YEAR(FSC_Coupon[[#This Row],[Service Date]]) -> 2026
A57: Goenka force Ghazipur | B57: Ghazipur | C57: 331201 | D57: 46140 | E57: 4949 | F57: Trax | G57: Inder Singh Kushwaha Sayar Gzp | H57: P001653 | I57: 46027 | J57: 0 | L57: =MONTH(FSC_Coupon[[#This Row],[Service Date]]) -> 4 | M57: =YEAR(FSC_Coupon[[#This Row],[Service Date]]) -> 2026
A58: Goenka force Ghazipur | B58: Ghazipur | C58: 327226 | D58: 46143 | E58: 28699 | F58: Trax | G58: Dalims Sunbeem School Gandhinagar Gzp | H58: P107009 | I58: 13/05/2026 | J58: 0 | L58: =MONTH(FSC_Coupon[[#This Row],[Service Date]]) -> 5 | M58: =YEAR(FSC_Coupon[[#This Row],[Service Date]]) -> 2026
A59: Goenka force Ghazipur | B59: Ghazipur | C59: 327227 | D59: 46143 | E59: 26224 | F59: Trax | G59: Dalims Sunbeem School Gandhinagar Gzp | H59: P107003 | I59: 13/05/2026 | J59: 0 | L59: =MONTH(FSC_Coupon[[#This Row],[Service Date]]) -> 5 | M59: =YEAR(FSC_Coupon[[#This Row],[Service Date]]) -> 2026
A60: Goenka force Ghazipur | B60: Ghazipur | C60: 334264 | D60: 46150 | E60: 2652 | F60: Trax | G60: Jagriti Pb School Yusufpur Ghazipur | H60: P114946 | I60: 13/05/2026 | J60: 500 | L60: =MONTH(FSC_Coupon[[#This Row],[Service Date]]) -> 5 | M60: =YEAR(FSC_Coupon[[#This Row],[Service Date]]) -> 2026
A61: Goenka force Ghazipur | B61: Ghazipur | C61: 336010 | D61: 46150 | E61: 3520 | F61: Trax | G61: Rajan Kumar Dhanvata Zamania Gzp | H61: P001690 | I61: 13/05/2026 | J61: 500 | L61: =MONTH(FSC_Coupon[[#This Row],[Service Date]]) -> 5 | M61: =YEAR(FSC_Coupon[[#This Row],[Service Date]]) -> 2026
A62: Goenka force Ghazipur | B62: Ghazipur | C62: 798838 | D62: 46150 | E62: 40691 | F62: T1 | G62: Raghunadan Kishundev Narsing College Devchandpur Gzp | H62: P055929 | I62: 28/05/2026 | J62: 0 | L62: =MONTH(FSC_Coupon[[#This Row],[Service Date]]) -> 5 | M62: =YEAR(FSC_Coupon[[#This Row],[Service Date]]) -> 2026
A63: Goenka force Ghazipur | B63: Ghazipur | C63: 328366 | D63: 46152 | E63: 19124 | F63: Trax | G63: Pramod Kumar Kushwaha Gahmar Gzp | H63: P001633 | I63: 28/05/2026 | J63: 500 | L63: =MONTH(FSC_Coupon[[#This Row],[Service Date]]) -> 5 | M63: =YEAR(FSC_Coupon[[#This Row],[Service Date]]) -> 2026
